Workbook

Sheet 说明
A1: 还债表 · 赛博老爸开源版 v1（2026 年 10 月）
A3: 这张表帮你做三件事：把所有债摊开看清楚；算出每个月至少要赚多少；算出用「雪球法」和「雪崩法」各自哪天能还清。
A5: 怎么用（4 步）
A6: 1. 打开「债务清单」，把每一笔债填进去（最多 10 笔）。里面的 4 行是示例，换成你自己的。
A7: 2. 打开「每月预算」，填收入和必要开支，再填每个月打算多还多少（加速钱），选一种还法。
A8: 3. 看「两种还法对比」：哪种更省利息，哪种能更快清掉第一笔。
A9: 4. 每个月照着「每月还款表」还。每周更新一次「债务清单」里的「还剩多少」。
A11: 颜色说明
A12: 黄底蓝字 = 你要填的格子。黑字 = 自动计算的，不要改。
A13: 「债务清单」里年化超过 24% 的会标红：银行、消费金融、正规网贷的个人贷款，监管要求利息加各种费用的年化不超过 24%，超过的可以打 12378 投诉。
A15: 不知道自己的真实年化？
A16: 用「利率换算」页：日息、月息、分期手续费、只知道每期还多少，都能换算成年化。
... A26: 免责：这张表只做计算，不构成法律意见或投资建议。具体以合同、银行和平台的官方答复为准。

Sheet 债务清单
A1: 债务清单
A2: 黄底蓝字是你要填的。下面 4 行是示例，换成你自己的债（最多 10 笔）。利率填成 18% 这样的格式。
A4: # | B4: 欠谁的 | C4: 类型 | D4: 还剩多少（元） | E4: 真实年化 | F4: 每月最低还款（元） | G4: 每月几号还 | H4: 有没有逾期 | I4: 备注 | J4: 雪球法顺序 | K4: 雪崩法顺序 | L4: 雪球法：第几个月还清 | M4: 雪崩法：第几个月还清 | N4: 有效（辅助） | O4: 年化（辅助）
A5: 1 | B5: 信用卡A | C5: 信用卡 | D5: 38000 | E5: 0.18 | F5: 1900 | G5: 5 | H5: 否 | I5: 示例，换成你自己的 | J5: =IF(N5=1,COUNTIFS($N$5:$N$14,1,$D$5:$D$14,"<"&D5)+COUNTIFS($N$5:$N$14,1,$D$5:$D$14,D5,$A$5:$A$14,"<"&A5)+1,"") -> 4 | K5: =IF(N5=1,COUNTIFS($N$5:$N$14,1,$O$5:$O$14,">"&O5)+COUNTIFS($N$5:$N$14,1,$O$5:$O$14,O5,$A$5:$A$14,"<"&A5)+1,"") -> 2 | L5: =IF(N5=1,INDEX(计算_雪球!$G$5:$G$14,J5),"") -> 19 | M5: =IF(N5=1,INDEX(计算_雪崩!$G$5:$G$14,K5),"") -> 17 | N5: =IF(AND(B5<>"",N(D5)>0),1,0) -> 1 | O5: =IF(N(E5)>1,N(E5)/100,N(E5)) -> 0.18
A6: 2 | B6: 信用卡B（分期） | C6: 信用卡 | D6: 12000 | E6: 0.13 | F6: 1072 | G6: 10 | H6: 否 | I6: 分期手续费换算后约 13% | J6: =IF(N6=1,COUNTIFS($N$5:$N$14,1,$D$5:$D$14,"<"&D6)+COUNTIFS($N$5:$N$14,1,$D$5:$D$14,D6,$A$5:$A$14,"<"&A6)+1,"") -> 1 | K6: =IF(N6=1,COUNTIFS($N$5:$N$14,1,$O$5:$O$14,">"&O6)+COUNTIFS($N$5:$N$14,1,$O$5:$O$14,O6,$A$5:$A$14,"<"&A6)+1,"") -> 3 | L6: =IF(N6=1,INDEX(计算_雪球!$G$5:$G$14,J6),"") -> 7 | M6: =IF(N6=1,INDEX(计算_雪崩!$G$5:$G$14,K6),"") -> 12 | N6: =IF(AND(B6<>"",N(D6)>0),1,0) -> 1 | O6: =IF(N(E6)>1,N(E6)/100,N(E6)) -> 0.13
A7: 3 | B7: 网贷X | C7: 网贷 | D7: 25000 | E7: 0.24 | F7: 1350 | G7: 15 | H7: 否 | J7: =IF(N7=1,COUNTIFS($N$5:$N$14,1,$D$5:$D$14,"<"&D7)+COUNTIFS($N$5:$N$14,1,$D$5:$D$14,D7,$A$5:$A$14,"<"&A7)+1,"") -> 3 | K7: =IF(N7=1,COUNTIFS($N$5:$N$14,1,$O$5:$O$14,">"&O7)+COUNTIFS($N$5:$N$14,1,$O$5:$O$14,O7,$A$5:$A$14,"<"&A7)+1,"") -> 1 | L7: =IF(N7=1,INDEX(计算_雪球!$G$5:$G$14,J7),"") -> 17 | M7: =IF(N7=1,INDEX(计算_雪崩!$G$5:$G$14,K7),"") -> 13 | N7: =IF(AND(B7<>"",N(D7)>0),1,0) -> 1 | O7: =IF(N(E7)>1,N(E7)/100,N(E7)) -> 0.24
A8: 4 | B8: 亲友借款（老王） | C8: 亲友借款 | D8: 20000 | E8: 0 | F8: 500 | G8: 1 | H8: 否 | I8: 说好每月还 500 | J8: =IF(N8=1,COUNTIFS($N$5:$N$14,1,$D$5:$D$14,"<"&D8)+COUNTIFS($N$5:$N$14,1,$D$5:$D$14,D8,$A$5:$A$14,"<"&A8)+1,"") -> 2 | K8: =IF(N8=1,COUNTIFS($N$5:$N$14,1,$O$5:$O$14,">"&O8)+COUNTIFS($N$5:$N$14,1,$O$5:$O$14,O8,$A$5:$A$14,"<"&A8)+1,"") -> 4 | L8: =IF(N8=1,INDEX(计算_雪球!$G$5:$G$14,J8),"") -> 13 | M8: =IF(N8=1,INDEX(计算_雪崩!$G$5:$G$14,K8),"") -> 19 | N8: =IF(AND(B8<>"",N(D8)>0),1,0) -> 1 | O8: =IF(N(E8)>1,N(E8)/100,N(E8)) -> 0
A9: 5 | J9: =IF(N9=1,COUNTIFS($N$5:$N$14,1,$D$5:$D$14,"<"&D9)+COUNTIFS($N$5:$N$14,1,$D$5:$D$14,D9,$A$5:$A$14,"<"&A9)+1,"") | K9: =IF(N9=1,COUNTIFS($N$5:$N$14,1,$O$5:$O$14,">"&O9)+COUNTIFS($N$5:$N$14,1,$O$5:$O$14,O9,$A$5:$A$14,"<"&A9)+1,"") | L9: =IF(N9=1,INDEX(计算_雪球!$G$5:$G$14,J9),"") | M9: =IF(N9=1,INDEX(计算_雪崩!$G$5:$G$14,K9),"") | N9: =IF(AND(B9<>"",N(D9)>0),1,0) -> 0 | O9: =IF(N(E9)>1,N(E9)/100,N(E9)) -> 0
A10: 6 | J10: =IF(N10=1,COUNTIFS($N$5:$N$14,1,$D$5:$D$14,"<"&D10)+COUNTIFS($N$5:$N$14,1,$D$5:$D$14,D10,$A$5:$A$14,"<"&A10)+1,"") | K10: =IF(N10=1,COUNTIFS($N$5:$N$14,1,$O$5:$O$14,">"&O10)+COUNTIFS($N$5:$N$14,1,$O$5:$O$14,O10,$A$5:$A$14,"<"&A10)+1,"") | L10: =IF(N10=1,INDEX(计算_雪球!$G$5:$G$14,J10),"") | M10: =IF(N10=1,INDEX(计算_雪崩!$G$5:$G$14,K10),"") | N10: =IF(AND(B10<>"",N(D10)>0),1,0) -> 0 | O10: =IF(N(E10)>1,N(E10)/100,N(E10)) -> 0
A11: 7 | J11: =IF(N11=1,COUNTIFS($N$5:$N$14,1,$D$5:$D$14,"<"&D11)+COUNTIFS($N$5:$N$14,1,$D$5:$D$14,D11,$A$5:$A$14,"<"&A11)+1,"") | K11: =IF(N11=1,COUNTIFS($N$5:$N$14,1,$O$5:$O$14,">"&O11)+COUNTIFS($N$5:$N$14,1,$O$5:$O$14,O11,$A$5:$A$14,"<"&A11)+1,"") | L11: =IF(N11=1,INDEX(计算_雪球!$G$5:$G$14,J11),"") | M11: =IF(N11=1,INDEX(计算_雪崩!$G$5:$G$14,K11),"") | N11: =IF(AND(B11<>"",N(D11)>0),1,0) -> 0 | O11: =IF(N(E11)>1,N(E11)/100,N(E11)) -> 0
A12: 8 | J12: =IF(N12=1,COUNTIFS($N$5:$N$14,1,$D$5:$D$14,"<"&D12)+COUNTIFS($N$5:$N$14,1,$D$5:$D$14,D12,$A$5:$A$14,"<"&A12)+1,"") | K12: =IF(N12=1,COUNTIFS($N$5:$N$14,1,$O$5:$O$14,">"&O12)+COUNTIFS($N$5:$N$14,1,$O$5:$O$14,O12,$A$5:$A$14,"<"&A12)+1,"") | L12: =IF(N12=1,INDEX(计算_雪球!$G$5:$G$14,J12),"") | M12: =IF(N12=1,INDEX(计算_雪崩!$G$5:$G$14,K12),"") | N12: =IF(AND(B12<>"",N(D12)>0),1,0) -> 0 | O12: =IF(N(E12)>1,N(E12)/100,N(E12)) -> 0
A13: 9 | J13: =IF(N13=1,COUNTIFS($N$5:$N$14,1,$D$5:$D$14,"<"&D13)+COUNTIFS($N$5:$N$14,1,$D$5:$D$14,D13,$A$5:$A$14,"<"&A13)+1,"") | K13: =IF(N13=1,COUNTIFS($N$5:$N$14,1,$O$5:$O$14,">"&O13)+COUNTIFS($N$5:$N$14,1,$O$5:$O$14,O13,$A$5:$A$14,"<"&A13)+1,"") | L13: =IF(N13=1,INDEX(计算_雪球!$G$5:$G$14,J13),"") | M13: =IF(N13=1,INDEX(计算_雪崩!$G$5:$G$14,K13),"") | N13: =IF(AND(B13<>"",N(D13)>0),1,0) -> 0 | O13: =IF(N(E13)>1,N(E13)/100,N(E13)) -> 0
A14: 10 | J14: =IF(N14=1,COUNTIFS($N$5:$N$14,1,$D$5:$D$14,"<"&D14)+COUNTIFS($N$5:$N$14,1,$D$5:$D$14,D14,$A$5:$A$14,"<"&A14)+1,"") | K14: =IF(N14=1,COUNTIFS($N$5:$N$14,1,$O$5:$O$14,">"&O14)+COUNTIFS($N$5:$N$14,1,$O$5:$O$14,O14,$A$5:$A$14,"<"&A14)+1,"") | L14: =IF(N14=1,INDEX(计算_雪球!$G$5:$G$14,J14),"") | M14: =IF(N14=1,INDEX(计算_雪崩!$G$5:$G$14,K14),"") | N14: =IF(AND(B14<>"",N(D14)>0),1,0) -> 0 | O14: =IF(N(E14)>1,N(E14)/100,N(E14)) -> 0
B15: 合计 | D15: =SUMIF($N$5:$N$14,1,D5:D14) -> 95000 | F15: =SUMIF($N$5:$N$14,1,F5:F14) -> 4822
A17: 年化超过 24% 的会标红：持牌机构的个人贷款，监管要求综合年化不超过 24%，可以打 12378 投诉。不知道年化？用「利率换算」页。

Sheet 每月预算
A1: 每月预算
A2: 黄底蓝字是你要填的，按一个月来算。
A4: 每月收入
A5: 工资 / 主业 | B5: 9500
A6: 副业 | B6: 2000
A7: 其他收入 | B7: 0
A8: 收入合计 | B8: =SUM(B5:B7) -> 11500
A10: 每月必要开支
A11: 房租 / 房贷 | B11: 2000
A12: 吃饭 | B12: 1500
A13: 交通 | B13: 300
A14: 水电、话费、网费 | B14: 300
A15: 孩子、赡养老人 | B15: 800
A16: 保险、看病 | B16: 200
A17: 其他必要开支 | B17: 200
A18: 零花钱（建议留一点，不然坚持不下去） | B18: 300
A19: 开支合计 | B19: =SUM(B11:B18) -> 5600
A21: 还债
A22: 所有债的最低还款合计 | B22: =债务清单!F15 -> 4822 | C22: 自动从「债务清单」拿过来
A23: 每个月至少要赚多少 | B23: =B19+B22 -> 10422 | C23: 也就是：必要开支 + 所有最低还款。低于这个数，就会越欠越多
A24: 每月结余（收入 − 开支 − 最低还款） | B24: =B8-B19-B22 -> 1078 | C24: =IF(B24<0,"【注意】收入不够还最低还款。先看 SOP 第三步，去协商降低月供","收入够覆盖最低还款") -> 收入够覆盖最低还款
A26: 每月打算多还的「加速钱」 | B26: 1000 | C26: =IF(N(B26)>MAX(0,B24),"【注意】加速钱比结余还多，月底会不够用","最多可以拿出 "&TEXT(MAX(0,B24),"#,##0")&" 元") -> 最多可以拿出 1,078 元
A27: 每月还款总预算（最低还款 + 加速钱） | B27: =B22+N(B26) -> 5822
A29: 还款办法 | B29: 雪球法 | C29: 雪球法 = 先还金额最小的；雪崩法 = 先还利息最高的
A30: 从哪个月开始 | B30: 46327
A32: 结果
A33: 还清需要几个月 | B33: =IF($B$29="雪崩法",计算_雪崩!C18,计算_雪球!C18) -> 19
A34: 预计哪个月还清 | B34: =IF(ISNUMBER(B33),IF(B33>0,EDATE(B30,B33-1),""),B33) -> 46874
A35: 总共要付的利息 | B35: =IF($B$29="雪崩法",计算_雪崩!C19,计算_雪球!C19) -> 12947.34
A36: 第一笔债第几个月还清 | B36: =IF($B$29="雪崩法",计算_雪崩!C20,计算_雪球!C20) -> 7

Sheet 两种还法对比
A1: 两种还法对比
A2: 两种办法用的是同一笔「每月还款总预算」，只是加速钱砸向的顺序不同。
B4: 雪球法（先还金额最小的） | C4: 雪崩法（先还利息最高的）
A5: 还清需要几个月 | B5: =计算_雪球!C18 -> 19 | C5: =计算_雪崩!C18 -> 19
A6: 预计哪个月还清 | B6: =IF(ISNUMBER(B5),IF(B5>0,EDATE(每月预算!$B$30,B5-1),""),B5) -> 46874 | C6: =IF(ISNUMBER(C5),IF(C5>0,EDATE(每月预算!$B$30,C5-1),""),C5) -> 46874
A7: 总共要付的利息 | B7: =计算_雪球!C19 -> 12947.34 | C7: =计算_雪崩!C19 -> 10505.63
A8: 第一笔债第几个月还清 | B8: =计算_雪球!C20 -> 7 | C8: =计算_雪崩!C20 -> 12
A10: 怎么选
A11: =IF(AND(ISNUMBER(B7),ISNUMBER(C7)),IF(B7-C7>=1,"雪崩法能少付 "&TEXT(B7-C7,"#,##0")&" 元利息；雪球法清掉第一笔会早一些（第 "&B8&" 个月 vs 第 "&C8&" 个月）。想省钱选雪崩法，怕坚持不住选雪球法。","两种办法差别不大，选让你更有动力的那个就行。"),"") -> 雪崩法能少付 2,442 元利息；雪球法清掉第一笔会早一些（第 7 个月 vs 第 12 个月）。想省钱选雪崩法，怕坚持不住选雪球法。
A14: 还款顺序 | B14: 雪球法：先还哪笔 | C14: 第几个月还清 | D14: 雪崩法：先还哪笔 | E14: 第几个月还清
A15: 1 | B15: =计算_雪球!C5 -> 信用卡B（分期） | C15: =计算_雪球!G5 -> 7 | D15: =计算_雪崩!C5 -> 网贷X | E15: =计算_雪崩!G5 -> 13
A16: 2 | B16: =计算_雪球!C6 -> 亲友借款（老王） | C16: =计算_雪球!G6 -> 13 | D16: =计算_雪崩!C6 -> 信用卡A | E16: =计算_雪崩!G6 -> 17
A17: 3 | B17: =计算_雪球!C7 -> 网贷X | C17: =计算_雪球!G7 -> 17 | D17: =计算_雪崩!C7 -> 信用卡B（分期） | E17: =计算_雪崩!G7 -> 12
A18: 4 | B18: =计算_雪球!C8 -> 信用卡A | C18: =计算_雪球!G8 -> 19 | D18: =计算_雪崩!C8 -> 亲友借款（老王） | E18: =计算_雪崩!G8 -> 19
A19: 5 | B19: =计算_雪球!C9 | C19: =计算_雪球!G9 | D19: =计算_雪崩!C9 | E19: =计算_雪崩!G9
A20: 6 | B20: =计算_雪球!C10 | C20: =计算_雪球!G10 | D20: =计算_雪崩!C10 | E20: =计算_雪崩!G10
A21: 7 | B21: =计算_雪球!C11 | C21: =计算_雪球!G11 | D21: =计算_雪崩!C11 | E21: =计算_雪崩!G11
A22: 8 | B22: =计算_雪球!C12 | C22: =计算_雪球!G12 | D22: =计算_雪崩!C12 | E22: =计算_雪崩!G12
A23: 9 | B23: =计算_雪球!C13 | C23: =计算_雪球!G13 | D23: =计算_雪崩!C13 | E23: =计算_雪崩!G13
A24: 10 | B24: =计算_雪球!C14 | C24: =计算_雪球!G14 | D24: =计算_雪崩!C14 | E24: =计算_雪崩!G14

Sheet 每月还款表
A1: ="每月还款表（"&每月预算!B29&"）" -> 每月还款表（雪球法）
A2: 每个月照着这张表还。「加速钱给了」那一列，就是这个月要多还的那一笔。想换办法，去「每月预算」改。 | Q2: 显示月数（辅助） | R2: =IF(ISNUMBER(每月预算!B33),每月预算!B33,240) -> 19
A4: 月份 | B4: 日期 | C4: =IF(每月预算!$B$29="雪崩法",计算_雪崩!$C$5,计算_雪球!$C$5) -> 信用卡B（分期） | D4: =IF(每月预算!$B$29="雪崩法",计算_雪崩!$C$6,计算_雪球!$C$6) -> 亲友借款（老王） | E4: =IF(每月预算!$B$29="雪崩法",计算_雪崩!$C$7,计算_雪球!$C$7) -> 网贷X | F4: =IF(每月预算!$B$29="雪崩法",计算_雪崩!$C$8,计算_雪球!$C$8) -> 信用卡A | G4: =IF(每月预算!$B$29="雪崩法",计算_雪崩!$C$9,计算_雪球!$C$9) | H4: =IF(每月预算!$B$29="雪崩法",计算_雪崩!$C$10,计算_雪球!$C$10) | I4: =IF(每月预算!$B$29="雪崩法",计算_雪崩!$C$11,计算_雪球!$C$11) | J4: =IF(每月预算!$B$29="雪崩法",计算_雪崩!$C$12,计算_雪球!$C$12) | K4: =IF(每月预算!$B$29="雪崩法",计算_雪崩!$C$13,计算_雪球!$C$13) | L4: =IF(每月预算!$B$29="雪崩法",计算_雪崩!$C$14,计算_雪球!$C$14) | M4: 本月一共还 | N4: 加速钱给了 | O4: 还完还剩
A5: =IF(1<=$R$2,1,"") -> 1 | B5: =IF($A5="","",计算_雪球!B24) -> 46327 | C5: =IF(OR($A5="",C$4=""),"",IF(每月预算!$B$29="雪崩法",计算_雪崩!I24,计算_雪球!I24)) -> 2072 | D5: =IF(OR($A5="",D$4=""),"",IF(每月预算!$B$29="雪崩法",计算_雪崩!N24,计算_雪球!N24)) -> 500 | E5: =IF(OR($A5="",E$4=""),"",IF(每月预算!$B$29="雪崩法",计算_雪崩!S24,计算_雪球!S24)) -> 1350 | F5: =IF(OR($A5="",F$4=""),"",IF(每月预算!$B$29="雪崩法",计算_雪崩!X24,计算_雪球!X24)) -> 1900 | G5: =IF(OR($A5="",G$4=""),"",IF(每月预算!$B$29="雪崩法",计算_雪崩!AC24,计算_雪球!AC24)) | H5: =IF(OR($A5="",H$4=""),"",IF(每月预算!$B$29="雪崩法",计算_雪崩!AH24,计算_雪球!AH24)) | I5: =IF(OR($A5="",I$4=""),"",IF(每月预算!$B$29="雪崩法",计算_雪崩!AM24,计算_雪球!AM24)) | J5: =IF(OR($A5="",J$4=""),"",IF(每月预算!$B$29="雪崩法",计算_雪崩!AR24,计算_雪球!AR24)) | K5: =IF(OR($A5="",K$4=""),"",IF(每月预算!$B$29="雪崩法",计算_雪崩!AW24,计算_雪球!AW24)) | L5: =IF(OR($A5="",L$4=""),"",IF(每月预算!$B$29="雪崩法",计算_雪崩!BB24,计算_雪球!BB24)) | M5: =IF($A5="","",IF(每月预算!$B$29="雪崩法",计算_雪崩!BC24,计算_雪球!BC24)) -> 5822 | N5: =IF($A5="","",IF(每月预算!$B$29="雪崩法",计算_雪崩!BE24,计算_雪球!BE24)) -> 信用卡B（分期） | O5: =IF($A5="","",IF(每月预算!$B$29="雪崩法",计算_雪崩!BD24,计算_雪球!BD24)) -> 90378
A6: =IF(2<=$R$2,2,"") -> 2 | B6: =IF($A6="","",计算_雪球!B25) -> 46357 | C6: =IF(OR($A6="",C$4=""),"",IF(每月预算!$B$29="雪崩法",计算_雪崩!I25,计算_雪球!I25)) -> 2072 | D6: =IF(OR($A6="",D$4=""),"",IF(每月预算!$B$29="雪崩法",计算_雪崩!N25,计算_雪球!N25)) -> 500 | E6: =IF(OR($A6="",E$4=""),"",IF(每月预算!$B$29="雪崩法",计算_雪崩!S25,计算_雪球!S25)) -> 1350 | F6: =IF(OR($A6="",F$4=""),"",IF(每月预算!$B$29="雪崩法",计算_雪崩!X25,计算_雪球!X25)) -> 1900 | G6: =IF(OR($A6="",G$4=""),"",IF(每月预算!$B$29="雪崩法",计算_雪崩!AC25,计算_雪球!AC25)) | H6: =IF(OR($A6="",H$4=""),"",IF(每月预算!$B$29="雪崩法",计算_雪崩!AH25,计算_雪球!AH25)) | I6: =IF(OR($A6="",I$4=""),"",IF(每月预算!$B$29="雪崩法",计算_雪崩!AM25,计算_雪球!AM25)) | J6: =IF(OR($A6="",J$4=""),"",IF(每月预算!$B$29="雪崩法",计算_雪崩!AR25,计算_雪球!AR25)) | K6: =IF(OR($A6="",K$4=""),"",IF(每月预算!$B$29="雪崩法",计算_雪崩!AW25,计算_雪球!AW25)) | L6: =IF(OR($A6="",L$4=""),"",IF(每月预算!$B$29="雪崩法",计算_雪崩!BB25,计算_雪球!BB25)) | M6: =IF($A6="","",IF(每月预算!$B$29="雪崩法",计算_雪崩!BC25,计算_雪球!BC25)) -> 5822 | N6: =IF($A6="","",IF(每月预算!$B$29="雪崩法",计算_雪崩!BE25,计算_雪球!BE25)) -> 信用卡B（分期） | O6: =IF($A6="","",IF(每月预算!$B$29="雪崩法",计算_雪崩!BD25,计算_雪球!BD25)) -> 85698.01
A7: =IF(3<=$R$2,3,"") -> 3 | B7: =IF($A7="","",计算_雪球!B26) -> 46388 | C7: =IF(OR($A7="",C$4=""),"",IF(每月预算!$B$29="雪崩法",计算_雪崩!I26,计算_雪球!I26)) -> 2072 | D7: =IF(OR($A7="",D$4=""),"",IF(每月预算!$B$29="雪崩法",计算_雪崩!N26,计算_雪球!N26)) -> 500 | E7: =IF(OR($A7="",E$4=""),"",IF(每月预算!$B$29="雪崩法",计算_雪崩!S26,计算_雪球!S26)) -> 1350 | F7: =IF(OR($A7="",F$4=""),"",IF(每月预算!$B$29="雪崩法",计算_雪崩!X26,计算_雪球!X26)) -> 1900 | G7: =IF(OR($A7="",G$4=""),"",IF(每月预算!$B$29="雪崩法",计算_雪崩!AC26,计算_雪球!AC26)) | H7: =IF(OR($A7="",H$4=""),"",IF(每月预算!$B$29="雪崩法",计算_雪崩!AH26,计算_雪球!AH26)) | I7: =IF(OR($A7="",I$4=""),"",IF(每月预算!$B$29="雪崩法",计算_雪崩!AM26,计算_雪球!AM26)) | J7: =IF(OR($A7="",J$4=""),"",IF(每月预算!$B$29="雪崩法",计算_雪崩!AR26,计算_雪球!AR26)) | K7: =IF(OR($A7="",K$4=""),"",IF(每月预算!$B$29="雪崩法",计算_雪崩!AW26,计算_雪球!AW26)) | L7: =IF(OR($A7="",L$4=""),"",IF(每月预算!$B$29="雪崩法",计算_雪崩!BB26,计算_雪球!BB26)) | M7: =IF($A7="","",IF(每月预算!$B$29="雪崩法",计算_雪崩!BC26,计算_雪球!BC26)) -> 5822 | N7: =IF($A7="","",IF(每月预算!$B$29="雪崩法",计算_雪崩!BE26,计算_雪球!BE26)) -> 信用卡B（分期） | O7: =IF($A7="","",IF(每月预算!$B$29="雪崩法",计算_雪崩!BD26,计算_雪球!BD26)) -> 80959.17
A8: =IF(4<=$R$2,4,"") -> 4 | B8: =IF($A8="","",计算_雪球!B27) -> 46419 | C8: =IF(OR($A8="",C$4=""),"",IF(每月预算!$B$29="雪崩法",计算_雪崩!I27,计算_雪球!I27)) -> 2072 | D8: =IF(OR($A8="",D$4=""),"",IF(每月预算!$B$29="雪崩法",计算_雪崩!N27,计算_雪球!N27)) -> 500 | E8: =IF(OR($A8="",E$4=""),"",IF(每月预算!$B$29="雪崩法",计算_雪崩!S27,计算_雪球!S27)) -> 1350 | F8: =IF(OR($A8="",F$4=""),"",IF(每月预算!$B$29="雪崩法",计算_雪崩!X27,计算_雪球!X27)) -> 1900 | G8: =IF(OR($A8="",G$4=""),"",IF(每月预算!$B$29="雪崩法",计算_雪崩!AC27,计算_雪球!AC27)) | H8: =IF(OR($A8="",H$4=""),"",IF(每月预算!$B$29="雪崩法",计算_雪崩!AH27,计算_雪球!AH27)) | I8: =IF(OR($A8="",I$4=""),"",IF(每月预算!$B$29="雪崩法",计算_雪崩!AM27,计算_雪球!AM27)) | J8: =IF(OR($A8="",J$4=""),"",IF(每月预算!$B$29="雪崩法",计算_雪崩!AR27,计算_雪球!AR27)) | K8: =IF(OR($A8="",K$4=""),"",IF(每月预算!$B$29="雪崩法",计算_雪崩!AW27,计算_雪球!AW27)) | L8: =IF(OR($A8="",L$4=""),"",IF(每月预算!$B$29="雪崩法",计算_雪崩!BB27,计算_雪球!BB27)) | M8: =IF($A8="","",IF(每月预算!$B$29="雪崩法",计算_雪崩!BC27,计算_雪球!BC27)) -> 5822 | N8: =IF($A8="","",IF(每月预算!$B$29="雪崩法",计算_雪崩!BE27,计算_雪球!BE27)) -> 信用卡B（分期） | O8: =IF($A8="","",IF(每月预算!$B$29="雪崩法",计算_雪崩!BD27,计算_雪球!BD27)) -> 76160.59
A9: =IF(5<=$R$2,5,"") -> 5 | B9: =IF($A9="","",计算_雪球!B28) -> 46447 | C9: =IF(OR($A9="",C$4=""),"",IF(每月预算!$B$29="雪崩法",计算_雪崩!I28,计算_雪球!I28)) -> 2072 | D9: =IF(OR($A9="",D$4=""),"",IF(每月预算!$B$29="雪崩法",计算_雪崩!N28,计算_雪球!N28)) -> 500 | E9: =IF(OR($A9="",E$4=""),"",IF(每月预算!$B$29="雪崩法",计算_雪崩!S28,计算_雪球!S28)) -> 1350 | F9: =IF(OR($A9="",F$4=""),"",IF(每月预算!$B$29="雪崩法",计算_雪崩!X28,计算_雪球!X28)) -> 1900 | G9: =IF(OR($A9="",G$4=""),"",IF(每月预算!$B$29="雪崩法",计算_雪崩!AC28,计算_雪球!AC28)) | H9: =IF(OR($A9="",H$4=""),"",IF(每月预算!$B$29="雪崩法",计算_雪崩!AH28,计算_雪球!AH28)) | I9: =IF(OR($A9="",I$4=""),"",IF(每月预算!$B$29="雪崩法",计算_雪崩!AM28,计算_雪球!AM28)) | J9: =IF(OR($A9="",J$4=""),"",IF(每月预算!$B$29="雪崩法",计算_雪崩!AR28,计算_雪球!AR28)) | K9: =IF(OR($A9="",K$4=""),"",IF(每月预算!$B$29="雪崩法",计算_雪崩!AW28,计算_雪球!AW28)) | L9: =IF(OR($A9="",L$4=""),"",IF(每月预算!$B$29="雪崩法",计算_雪崩!BB28,计算_雪球!BB28)) | M9: =IF($A9="","",IF(每月预算!$B$29="雪崩法",计算_雪崩!BC28,计算_雪球!BC28)) -> 5822 | N9: =IF($A9="","",IF(每月预算!$B$29="雪崩法",计算_雪崩!BE28,计算_雪球!BE28)) -> 信用卡B（分期） | O9: =IF($A9="","",IF(每月预算!$B$29="雪崩法",计算_雪崩!BD28,计算_雪球!BD28)) -> 71301.38
A10: =IF(6<=$R$2,6,"") -> 6 | B10: =IF($A10="","",计算_雪球!B29) -> 46478 | C10: =IF(OR($A10="",C$4=""),"",IF(每月预算!$B$29="雪崩法",计算_雪崩!I29,计算_雪球!I29)) -> 2072 | D10: =IF(OR($A10="",D$4=""),"",IF(每月预算!$B$29="雪崩法",计算_雪崩!N29,计算_雪球!N29)) -> 500 | E10: =IF(OR($A10="",E$4=""),"",IF(每月预算!$B$29="雪崩法",计算_雪崩!S29,计算_雪球!S29)) -> 1350 | F10: =IF(OR($A10="",F$4=""),"",IF(每月预算!$B$29="雪崩法",计算_雪崩!X29,计算_雪球!X29)) -> 1900 | G10: =IF(OR($A10="",G$4=""),"",IF(每月预算!$B$29="雪崩法",计算_雪崩!AC29,计算_雪球!AC29)) | H10: =IF(OR($A10="",H$4=""),"",IF(每月预算!$B$29="雪崩法",计算_雪崩!AH29,计算_雪球!AH29)) | I10: =IF(OR($A10="",I$4=""),"",IF(每月预算!$B$29="雪崩法",计算_雪崩!AM29,计算_雪球!AM29)) | J10: =IF(OR($A10="",J$4=""),"",IF(每月预算!$B$29="雪崩法",计算_雪崩!AR29,计算_雪球!AR29)) | K10: =IF(OR($A10="",K$4=""),"",IF(每月预算!$B$29="雪崩法",计算_雪崩!AW29,计算_雪球!AW29)) | L10: =IF(OR($A10="",L$4=""),"",IF(每月预算!$B$29="雪崩法",计算_雪崩!BB29,计算_雪球!BB29)) | M10: =IF($A10="","",IF(每月预算!$B$29="雪崩法",计算_雪崩!BC29,计算_雪球!BC29)) -> 5822 | N10: =IF($A10="","",IF(每月预算!$B$29="雪崩法",计算_雪崩!BE29,计算_雪球!BE29)) -> 信用卡B（分期） | O10: =IF($A10="","",IF(每月预算!$B$29="雪崩法",计算_雪崩!BD29,计算_雪球!BD29)) -> 66380.62
A11: =IF(7<=$R$2,7,"") -> 7 | B11: =IF($A11="","",计算_雪球!B30) -> 46508 | C11: =IF(OR($A11="",C$4=""),"",IF(每月预算!$B$29="雪崩法",计算_雪崩!I30,计算_雪球!I30)) -> 28.13 | D11: =IF(OR($A11="",D$4=""),"",IF(每月预算!$B$29="雪崩法",计算_雪崩!N30,计算_雪球!N30)) -> 2543.87 | E11: =IF(OR($A11="",E$4=""),"",IF(每月预算!$B$29="雪崩法",计算_雪崩!S30,计算_雪球!S30)) -> 1350 | F11: =IF(OR($A11="",F$4=""),"",IF(每月预算!$B$29="雪崩法",计算_雪崩!X30,计算_雪球!X30)) -> 1900 | G11: =IF(OR($A11="",G$4=""),"",IF(每月预算!$B$29="雪崩法",计算_雪崩!AC30,计算_雪球!AC30)) | H11: =IF(OR($A11="",H$4=""),"",IF(每月预算!$B$29="雪崩法",计算_雪崩!AH30,计算_雪球!AH30)) | I11: =IF(OR($A11="",I$4=""),"",IF(每月预算!$B$29="雪崩法",计算_雪崩!AM30,计算_雪球!AM30)) | J11: =IF(OR($A11="",J$4=""),"",IF(每月预算!$B$29="雪崩法",计算_雪崩!AR30,计算_雪球!AR30)) | K11: =IF(OR($A11="",K$4=""),"",IF(每月预算!$B$29="雪崩法",计算_雪崩!AW30,计算_雪球!AW30)) | L11: =IF(OR($A11="",L$4=""),"",IF(每月预算!$B$29="雪崩法",计算_雪崩!BB30,计算_雪球!BB30)) | M11: =IF($A11="","",IF(每月预算!$B$29="雪崩法",计算_雪崩!BC30,计算_雪球!BC30)) -> 5822 | N11: =IF($A11="","",IF(每月预算!$B$29="雪崩法",计算_雪崩!BE30,计算_雪球!BE30)) -> 亲友借款（老王） | O11: =IF($A11="","",IF(每月预算!$B$29="雪崩法",计算_雪崩!BD30,计算_雪球!BD30)) -> 61397.4
A12: =IF(8<=$R$2,8,"") -> 8 | B12: =IF($A12="","",计算_雪球!B31) -> 46539 | C12: =IF(OR($A12="",C$4=""),"",IF(每月预算!$B$29="雪崩法",计算_雪崩!I31,计算_雪球!I31)) -> 0 | D12: =IF(OR($A12="",D$4=""),"",IF(每月预算!$B$29="雪崩法",计算_雪崩!N31,计算_雪球!N31)) -> 2572 | E12: =IF(OR($A12="",E$4=""),"",IF(每月预算!$B$29="雪崩法",计算_雪崩!S31,计算_雪球!S31)) -> 1350 | F12: =IF(OR($A12="",F$4=""),"",IF(每月预算!$B$29="雪崩法",计算_雪崩!X31,计算_雪球!X31)) -> 1900 | G12: =IF(OR($A12="",G$4=""),"",IF(每月预算!$B$29="雪崩法",计算_雪崩!AC31,计算_雪球!AC31)) | H12: =IF(OR($A12="",H$4=""),"",IF(每月预算!$B$29="雪崩法",计算_雪崩!AH31,计算_雪球!AH31)) | I12: =IF(OR($A12="",I$4=""),"",IF(每月预算!$B$29="雪崩法",计算_雪崩!AM31,计算_雪球!AM31)) | J12: =IF(OR($A12="",J$4=""),"",IF(每月预算!$B$29="雪崩法",计算_雪崩!AR31,计算_雪球!AR31)) | K12: =IF(OR($A12="",K$4=""),"",IF(每月预算!$B$29="雪崩法",计算_雪崩!AW31,计算_雪球!AW31)) | L12: =IF(OR($A12="",L$4=""),"",IF(每月预算!$B$29="雪崩法",计算_雪崩!BB31,计算_雪球!BB31)) | M12: =IF($A12="","",IF(每月预算!$B$29="雪崩法",计算_雪崩!BC31,计算_雪球!BC31)) -> 5822 | N12: =IF($A12="","",IF(每月预算!$B$29="雪崩法",计算_雪崩!BE31,计算_雪球!BE31)) -> 亲友借款（老王） | O12: =IF($A12="","",IF(每月预算!$B$29="雪崩法",计算_雪崩!BD31,计算_雪球!BD31)) -> 56372.93
A13: =IF(9<=$R$2,9,"") -> 9 | B13: =IF($A13="","",计算_雪球!B32) -> 46569 | C13: =IF(OR($A13="",C$4=""),"",IF(每月预算!$B$29="雪崩法",计算_雪崩!I32,计算_雪球!I32)) -> 0 | D13: =IF(OR($A13="",D$4=""),"",IF(每月预算!$B$29="雪崩法",计算_雪崩!N32,计算_雪球!N32)) -> 2572 | E13: =IF(OR($A13="",E$4=""),"",IF(每月预算!$B$29="雪崩法",计算_雪崩!S32,计算_雪球!S32)) -> 1350 | F13: =IF(OR($A13="",F$4=""),"",IF(每月预算!$B$29="雪崩法",计算_雪崩!X32,计算_雪球!X32)) -> 1900 | G13: =IF(OR($A13="",G$4=""),"",IF(每月预算!$B$29="雪崩法",计算_雪崩!AC32,计算_雪球!AC32)) | H13: =IF(OR($A13="",H$4=""),"",IF(每月预算!$B$29="雪崩法",计算_雪崩!AH32,计算_雪球!AH32)) | I13: =IF(OR($A13="",I$4=""),"",IF(每月预算!$B$29="雪崩法",计算_雪崩!AM32,计算_雪球!AM32)) | J13: =IF(OR($A13="",J$4=""),"",IF(每月预算!$B$29="雪崩法",计算_雪崩!AR32,计算_雪球!AR32)) | K13: =IF(OR($A13="",K$4=""),"",IF(每月预算!$B$29="雪崩法",计算_雪崩!AW32,计算_雪球!AW32)) | L13: =IF(OR($A13="",L$4=""),"",IF(每月预算!$B$29="雪崩法",计算_雪崩!BB32,计算_雪球!BB32)) | M13: =IF($A13="","",IF(每月预算!$B$29="雪崩法",计算_雪崩!BC32,计算_雪球!BC32)) -> 5822 | N13: =IF($A13="","",IF(每月预算!$B$29="雪崩法",计算_雪崩!BE32,计算_雪球!BE32)) -> 亲友借款（老王） | O13: =IF($A13="","",IF(每月预算!$B$29="雪崩法",计算_雪崩!BD32,计算_雪球!BD32)) -> 51306.78
A14: =IF(10<=$R$2,10,"") -> 10 | B14: =IF($A14="","",计算_雪球!B33) -> 46600 | C14: =IF(OR($A14="",C$4=""),"",IF(每月预算!$B$29="雪崩法",计算_雪崩!I33,计算_雪球!I33)) -> 0 | D14: =IF(OR($A14="",D$4=""),"",IF(每月预算!$B$29="雪崩法",计算_雪崩!N33,计算_雪球!N33)) -> 2572 | E14: =IF(OR($A14="",E$4=""),"",IF(每月预算!$B$29="雪崩法",计算_雪崩!S33,计算_雪球!S33)) -> 1350 | F14: =IF(OR($A14="",F$4=""),"",IF(每月预算!$B$29="雪崩法",计算_雪崩!X33,计算_雪球!X33)) -> 1900 | G14: =IF(OR($A14="",G$4=""),"",IF(每月预算!$B$29="雪崩法",计算_雪崩!AC33,计算_雪球!AC33)) | H14: =IF(OR($A14="",H$4=""),"",IF(每月预算!$B$29="雪崩法",计算_雪崩!AH33,计算_雪球!AH33)) | I14: =IF(OR($A14="",I$4=""),"",IF(每月预算!$B$29="雪崩法",计算_雪崩!AM33,计算_雪球!AM33)) | J14: =IF(OR($A14="",J$4=""),"",IF(每月预算!$B$29="雪崩法",计算_雪崩!AR33,计算_雪球!AR33)) | K14: =IF(OR($A14="",K$4=""),"",IF(每月预算!$B$29="雪崩法",计算_雪崩!AW33,计算_雪球!AW33)) | L14: =IF(OR($A14="",L$4=""),"",IF(每月预算!$B$29="雪崩法",计算_雪崩!BB33,计算_雪球!BB33)) | M14: =IF($A14="","",IF(每月预算!$B$29="雪崩法",计算_雪崩!BC33,计算_雪球!BC33)) -> 5822 | N14: =IF($A14="","",IF(每月预算!$B$29="雪崩法",计算_雪崩!BE33,计算_雪球!BE33)) -> 亲友借款（老王） | O14: =IF($A14="","",IF(每月预算!$B$29="雪崩法",计算_雪崩!BD33,计算_雪球!BD33)) -> 46198.24
A15: =IF(11<=$R$2,11,"") -> 11 | B15: =IF($A15="","",计算_雪球!B34) -> 46631 | C15: =IF(OR($A15="",C$4=""),"",IF(每月预算!$B$29="雪崩法",计算_雪崩!I34,计算_雪球!I34)) -> 0 | D15: =IF(OR($A15="",D$4=""),"",IF(每月预算!$B$29="雪崩法",计算_雪崩!N34,计算_雪球!N34)) -> 2572 | E15: =IF(OR($A15="",E$4=""),"",IF(每月预算!$B$29="雪崩法",计算_雪崩!S34,计算_雪球!S34)) -> 1350 | F15: =IF(OR($A15="",F$4=""),"",IF(每月预算!$B$29="雪崩法",计算_雪崩!X34,计算_雪球!X34)) -> 1900 | G15: =IF(OR($A15="",G$4=""),"",IF(每月预算!$B$29="雪崩法",计算_雪崩!AC34,计算_雪球!AC34)) | H15: =IF(OR($A15="",H$4=""),"",IF(每月预算!$B$29="雪崩法",计算_雪崩!AH34,计算_雪球!AH34)) | I15: =IF(OR($A15="",I$4=""),"",IF(每月预算!$B$29="雪崩法",计算_雪崩!AM34,计算_雪球!AM34)) | J15: =IF(OR($A15="",J$4=""),"",IF(每月预算!$B$29="雪崩法",计算_雪崩!AR34,计算_雪球!AR34)) | K15: =IF(OR($A15="",K$4=""),"",IF(每月预算!$B$29="雪崩法",计算_雪崩!AW34,计算_雪球!AW34)) | L15: =IF(OR($A15="",L$4=""),"",IF(每月预算!$B$29="雪崩法",计算_雪崩!BB34,计算_雪球!BB34)) | M15: =IF($A15="","",IF(每月预算!$B$29="雪崩法",计算_雪崩!BC34,计算_雪球!BC34)) -> 5822 | N15: =IF($A15="","",IF(每月预算!$B$29="雪崩法",计算_雪崩!BE34,计算_雪球!BE34)) -> 亲友借款（老王） | O15: =IF($A15="","",IF(每月预算!$B$29="雪崩法",计算_雪崩!BD34,计算_雪球!BD34)) -> 41046.57
A16: =IF(12<=$R$2,12,"") -> 12 | B16: =IF($A16="","",计算_雪球!B35) -> 46661 | C16: =IF(OR($A16="",C$4=""),"",IF(每月预算!$B$29="雪崩法",计算_雪崩!I35,计算_雪球!I35)) -> 0 | D16: =IF(OR($A16="",D$4=""),"",IF(每月预算!$B$29="雪崩法",计算_雪崩!N35,计算_雪球!N35)) -> 2572 | E16: =IF(OR($A16="",E$4=""),"",IF(每月预算!$B$29="雪崩法",计算_雪崩!S35,计算_雪球!S35)) -> 1350 | F16: =IF(OR($A16="",F$4=""),"",IF(每月预算!$B$29="雪崩法",计算_雪崩!X35,计算_雪球!X35)) -> 1900 | G16: =IF(OR($A16="",G$4=""),"",IF(每月预算!$B$29="雪崩法",计算_雪崩!AC35,计算_雪球!AC35)) | H16: =IF(OR($A16="",H$4=""),"",IF(每月预算!$B$29="雪崩法",计算_雪崩!AH35,计算_雪球!AH35)) | I16: =IF(OR($A16="",I$4=""),"",IF(每月预算!$B$29="雪崩法",计算_雪崩!AM35,计算_雪球!AM35)) | J16: =IF(OR($A16="",J$4=""),"",IF(每月预算!$B$29="雪崩法",计算_雪崩!AR35,计算_雪球!AR35)) | K16: =IF(OR($A16="",K$4=""),"",IF(每月预算!$B$29="雪崩法",计算_雪崩!AW35,计算_雪球!AW35)) | L16: =IF(OR($A16="",L$4=""),"",IF(每月预算!$B$29="雪崩法",计算_雪崩!BB35,计算_雪球!BB35)) | M16: =IF($A16="","",IF(每月预算!$B$29="雪崩法",计算_雪崩!BC35,计算_雪球!BC35)) -> 5822 | N16: =IF($A16="","",IF(每月预算!$B$29="雪崩法",计算_雪崩!BE35,计算_雪球!BE35)) -> 亲友借款（老王） | O16: =IF($A16="","",IF(每月预算!$B$29="雪崩法",计算_雪崩!BD35,计算_雪球!BD35)) -> 35851.03
A17: =IF(13<=$R$2,13,"") -> 13 | B17: =IF($A17="","",计算_雪球!B36) -> 46692 | C17: =IF(OR($A17="",C$4=""),"",IF(每月预算!$B$29="雪崩法",计算_雪崩!I36,计算_雪球!I36)) -> 0 | D17: =IF(OR($A17="",D$4=""),"",IF(每月预算!$B$29="雪崩法",计算_雪崩!N36,计算_雪球!N36)) -> 1596.13 | E17: =IF(OR($A17="",E$4=""),"",IF(每月预算!$B$29="雪崩法",计算_雪崩!S36,计算_雪球!S36)) -> 2325.87 | F17: =IF(OR($A17="",F$4=""),"",IF(每月预算!$B$29="雪崩法",计算_雪崩!X36,计算_雪球!X36)) -> 1900 | G17: =IF(OR($A17="",G$4=""),"",IF(每月预算!$B$29="雪崩法",计算_雪崩!AC36,计算_雪球!AC36)) | H17: =IF(OR($A17="",H$4=""),"",IF(每月预算!$B$29="雪崩法",计算_雪崩!AH36,计算_雪球!AH36)) | I17: =IF(OR($A17="",I$4=""),"",IF(每月预算!$B$29="雪崩法",计算_雪崩!AM36,计算_雪球!AM36)) | J17: =IF(OR($A17="",J$4=""),"",IF(每月预算!$B$29="雪崩法",计算_雪崩!AR36,计算_雪球!AR36)) | K17: =IF(OR($A17="",K$4=""),"",IF(每月预算!$B$29="雪崩法",计算_雪崩!AW36,计算_雪球!AW36)) | L17: =IF(OR($A17="",L$4=""),"",IF(每月预算!$B$29="雪崩法",计算_雪崩!BB36,计算_雪球!BB36)) | M17: =IF($A17="","",IF(每月预算!$B$29="雪崩法",计算_雪崩!BC36,计算_雪球!BC36)) -> 5822 | N17: =IF($A17="","",IF(每月预算!$B$29="雪崩法",计算_雪崩!BE36,计算_雪球!BE36)) -> 亲友借款（老王） | O17: =IF($A17="","",IF(每月预算!$B$29="雪崩法",计算_雪崩!BD36,计算_雪球!BD36)) -> 30610.85
A18: =IF(14<=$R$2,14,"") -> 14 | B18: =IF($A18="","",计算_雪球!B37) -> 46722 | C18: =IF(OR($A18="",C$4=""),"",IF(每月预算!$B$29="雪崩法",计算_雪崩!I37,计算_雪球!I37)) -> 0 | D18: =IF(OR($A18="",D$4=""),"",IF(每月预算!$B$29="雪崩法",计算_雪崩!N37,计算_雪球!N37)) -> 0 | E18: =IF(OR($A18="",E$4=""),"",IF(每月预算!$B$29="雪崩法",计算_雪崩!S37,计算_雪球!S37)) -> 3922 | F18: =IF(OR($A18="",F$4=""),"",IF(每月预算!$B$29="雪崩法",计算_雪崩!X37,计算_雪球!X37)) -> 1900 | G18: =IF(OR($A18="",G$4=""),"",IF(每月预算!$B$29="雪崩法",计算_雪崩!AC37,计算_雪球!AC37)) | H18: =IF(OR($A18="",H$4=""),"",IF(每月预算!$B$29="雪崩法",计算_雪崩!AH37,计算_雪球!AH37)) | I18: =IF(OR($A18="",I$4=""),"",IF(每月预算!$B$29="雪崩法",计算_雪崩!AM37,计算_雪球!AM37)) | J18: =IF(OR($A18="",J$4=""),"",IF(每月预算!$B$29="雪崩法",计算_雪崩!AR37,计算_雪球!AR37)) | K18: =IF(OR($A18="",K$4=""),"",IF(每月预算!$B$29="雪崩法",计算_雪崩!AW37,计算_雪球!AW37)) | L18: =IF(OR($A18="",L$4=""),"",IF(每月预算!$B$29="雪崩法",计算_雪崩!BB37,计算_雪球!BB37)) | M18: =IF($A18="","",IF(每月预算!$B$29="雪崩法",计算_雪崩!BC37,计算_雪球!BC37)) -> 5822 | N18: =IF($A18="","",IF(每月预算!$B$29="雪崩法",计算_雪崩!BE37,计算_雪球!BE37)) -> 网贷X | O18: =IF($A18="","",IF(每月预算!$B$29="雪崩法",计算_雪崩!BD37,计算_雪球!BD37)) -> 25305.75
A19: =IF(15<=$R$2,15,"") -> 15 | B19: =IF($A19="","",计算_雪球!B38) -> 46753 | C19: =IF(OR($A19="",C$4=""),"",IF(每月预算!$B$29="雪崩法",计算_雪崩!I38,计算_雪球!I38)) -> 0 | D19: =IF(OR($A19="",D$4=""),"",IF(每月预算!$B$29="雪崩法",计算_雪崩!N38,计算_雪球!N38)) -> 0 | E19: =IF(OR($A19="",E$4=""),"",IF(每月预算!$B$29="雪崩法",计算_雪崩!S38,计算_雪球!S38)) -> 3922 | F19: =IF(OR($A19="",F$4=""),"",IF(每月预算!$B$29="雪崩法",计算_雪崩!X38,计算_雪球!X38)) -> 1900 | G19: =IF(OR($A19="",G$4=""),"",IF(每月预算!$B$29="雪崩法",计算_雪崩!AC38,计算_雪球!AC38)) | H19: =IF(OR($A19="",H$4=""),"",IF(每月预算!$B$29="雪崩法",计算_雪崩!AH38,计算_雪球!AH38)) | I19: =IF(OR($A19="",I$4=""),"",IF(每月预算!$B$29="雪崩法",计算_雪崩!AM38,计算_雪球!AM38)) | J19: =IF(OR($A19="",J$4=""),"",IF(每月预算!$B$29="雪崩法",计算_雪崩!AR38,计算_雪球!AR38)) | K19: =IF(OR($A19="",K$4=""),"",IF(每月预算!$B$29="雪崩法",计算_雪崩!AW38,计算_雪球!AW38)) | L19: =IF(OR($A19="",L$4=""),"",IF(每月预算!$B$29="雪崩法",计算_雪崩!BB38,计算_雪球!BB38)) | M19: =IF($A19="","",IF(每月预算!$B$29="雪崩法",计算_雪崩!BC38,计算_雪球!BC38)) -> 5822 | N19: =IF($A19="","",IF(每月预算!$B$29="雪崩法",计算_雪崩!BE38,计算_雪球!BE38)) -> 网贷X | O19: =IF($A19="","",IF(每月预算!$B$29="雪崩法",计算_雪崩!BD38,计算_雪球!BD38)) -> 19902.62
A20: =IF(16<=$R$2,16,"") -> 16 | B20: =IF($A20="","",计算_雪球!B39) -> 46784 | C20: =IF(OR($A20="",C$4=""),"",IF(每月预算!$B$29="雪崩法",计算_雪崩!I39,计算_雪球!I39)) -> 0 | D20: =IF(OR($A20="",D$4=""),"",IF(每月预算!$B$29="雪崩法",计算_雪崩!N39,计算_雪球!N39)) -> 0 | E20: =IF(OR($A20="",E$4=""),"",IF(每月预算!$B$29="雪崩法",计算_雪崩!S39,计算_雪球!S39)) -> 3922 | F20: =IF(OR($A20="",F$4=""),"",IF(每月预算!$B$29="雪崩法",计算_雪崩!X39,计算_雪球!X39)) -> 1900 | G20: =IF(OR($A20="",G$4=""),"",IF(每月预算!$B$29="雪崩法",计算_雪崩!AC39,计算_雪球!AC39)) | H20: =IF(OR($A20="",H$4=""),"",IF(每月预算!$B$29="雪崩法",计算_雪崩!AH39,计算_雪球!AH39)) | I20: =IF(OR($A20="",I$4=""),"",IF(每月预算!$B$29="雪崩法",计算_雪崩!AM39,计算_雪球!AM39)) | J20: =IF(OR($A20="",J$4=""),"",IF(每月预算!$B$29="雪崩法",计算_雪崩!AR39,计算_雪球!AR39)) | K20: =IF(OR($A20="",K$4=""),"",IF(每月预算!$B$29="雪崩法",计算_雪崩!AW39,计算_雪球!AW39)) | L20: =IF(OR($A20="",L$4=""),"",IF(每月预算!$B$29="雪崩法",计算_雪崩!BB39,计算_雪球!BB39)) | M20: =IF($A20="","",IF(每月预算!$B$29="雪崩法",计算_雪崩!BC39,计算_雪球!BC39)) -> 5822 | N20: =IF($A20="","",IF(每月预算!$B$29="雪崩法",计算_雪崩!BE39,计算_雪球!BE39)) -> 网贷X | O20: =IF($A20="","",IF(每月预算!$B$29="雪崩法",计算_雪崩!BD39,计算_雪球!BD39)) -> 14399.61
A21: =IF(17<=$R$2,17,"") -> 17 | B21: =IF($A21="","",计算_雪球!B40) -> 46813 | C21: =IF(OR($A21="",C$4=""),"",IF(每月预算!$B$29="雪崩法",计算_雪崩!I40,计算_雪球!I40)) -> 0 | D21: =IF(OR($A21="",D$4=""),"",IF(每月预算!$B$29="雪崩法",计算_雪崩!N40,计算_雪球!N40)) -> 0 | E21: =IF(OR($A21="",E$4=""),"",IF(每月预算!$B$29="雪崩法",计算_雪崩!S40,计算_雪球!S40)) -> 254.64 | F21: =IF(OR($A21="",F$4=""),"",IF(每月预算!$B$29="雪崩法",计算_雪崩!X40,计算_雪球!X40)) -> 5567.36 | G21: =IF(OR($A21="",G$4=""),"",IF(每月预算!$B$29="雪崩法",计算_雪崩!AC40,计算_雪球!AC40)) | H21: =IF(OR($A21="",H$4=""),"",IF(每月预算!$B$29="雪崩法",计算_雪崩!AH40,计算_雪球!AH40)) | I21: =IF(OR($A21="",I$4=""),"",IF(每月预算!$B$29="雪崩法",计算_雪崩!AM40,计算_雪球!AM40)) | J21: =IF(OR($A21="",J$4=""),"",IF(每月预算!$B$29="雪崩法",计算_雪崩!AR40,计算_雪球!AR40)) | K21: =IF(OR($A21="",K$4=""),"",IF(每月预算!$B$29="雪崩法",计算_雪崩!AW40,计算_雪球!AW40)) | L21: =IF(OR($A21="",L$4=""),"",IF(每月预算!$B$29="雪崩法",计算_雪崩!BB40,计算_雪球!BB40)) | M21: =IF($A21="","",IF(每月预算!$B$29="雪崩法",计算_雪崩!BC40,计算_雪球!BC40)) -> 5822 | N21: =IF($A21="","",IF(每月预算!$B$29="雪崩法",计算_雪崩!BE40,计算_雪球!BE40)) -> 信用卡A | O21: =IF($A21="","",IF(每月预算!$B$29="雪崩法",计算_雪崩!BD40,计算_雪球!BD40)) -> 8794.85
A22: =IF(18<=$R$2,18,"") -> 18 | B22: =IF($A22="","",计算_雪球!B41) -> 46844 | C22: =IF(OR($A22="",C$4=""),"",IF(每月预算!$B$29="雪崩法",计算_雪崩!I41,计算_雪球!I41)) -> 0 | D22: =IF(OR($A22="",D$4=""),"",IF(每月预算!$B$29="雪崩法",计算_雪崩!N41,计算_雪球!N41)) -> 0 | E22: =IF(OR($A22="",E$4=""),"",IF(每月预算!$B$29="雪崩法",计算_雪崩!S41,计算_雪球!S41)) -> 0 | F22: =IF(OR($A22="",F$4=""),"",IF(每月预算!$B$29="雪崩法",计算_雪崩!X41,计算_雪球!X41)) -> 5822 | G22: =IF(OR($A22="",G$4=""),"",IF(每月预算!$B$29="雪崩法",计算_雪崩!AC41,计算_雪球!AC41)) | H22: =IF(OR($A22="",H$4=""),"",IF(每月预算!$B$29="雪崩法",计算_雪崩!AH41,计算_雪球!AH41)) | I22: =IF(OR($A22="",I$4=""),"",IF(每月预算!$B$29="雪崩法",计算_雪崩!AM41,计算_雪球!AM41)) | J22: =IF(OR($A22="",J$4=""),"",IF(每月预算!$B$29="雪崩法",计算_雪崩!AR41,计算_雪球!AR41)) | K22: =IF(OR($A22="",K$4=""),"",IF(每月预算!$B$29="雪崩法",计算_雪崩!AW41,计算_雪球!AW41)) | L22: =IF(OR($A22="",L$4=""),"",IF(每月预算!$B$29="雪崩法",计算_雪崩!BB41,计算_雪球!BB41)) | M22: =IF($A22="","",IF(每月预算!$B$29="雪崩法",计算_雪崩!BC41,计算_雪球!BC41)) -> 5822 | N22: =IF($A22="","",IF(每月预算!$B$29="雪崩法",计算_雪崩!BE41,计算_雪球!BE41)) -> 信用卡A | O22: =IF($A22="","",IF(每月预算!$B$29="雪崩法",计算_雪崩!BD41,计算_雪球!BD41)) -> 3104.77
A23: =IF(19<=$R$2,19,"") -> 19 | B23: =IF($A23="","",计算_雪球!B42) -> 46874 | C23: =IF(OR($A23="",C$4=""),"",IF(每月预算!$B$29="雪崩法",计算_雪崩!I42,计算_雪球!I42)) -> 0 | D23: =IF(OR($A23="",D$4=""),"",IF(每月预算!$B$29="雪崩法",计算_雪崩!N42,计算_雪球!N42)) -> 0 | E23: =IF(OR($A23="",E$4=""),"",IF(每月预算!$B$29="雪崩法",计算_雪崩!S42,计算_雪球!S42)) -> 0 | F23: =IF(OR($A23="",F$4=""),"",IF(每月预算!$B$29="雪崩法",计算_雪崩!X42,计算_雪球!X42)) -> 3151.34 | G23: =IF(OR($A23="",G$4=""),"",IF(每月预算!$B$29="雪崩法",计算_雪崩!AC42,计算_雪球!AC42)) | H23: =IF(OR($A23="",H$4=""),"",IF(每月预算!$B$29="雪崩法",计算_雪崩!AH42,计算_雪球!AH42)) | I23: =IF(OR($A23="",I$4=""),"",IF(每月预算!$B$29="雪崩法",计算_雪崩!AM42,计算_雪球!AM42)) | J23: =IF(OR($A23="",J$4=""),"",IF(每月预算!$B$29="雪崩法",计算_雪崩!AR42,计算_雪球!AR42)) | K23: =IF(OR($A23="",K$4=""),"",IF(每月预算!$B$29="雪崩法",计算_雪崩!AW42,计算_雪球!AW42)) | L23: =IF(OR($A23="",L$4=""),"",IF(每月预算!$B$29="雪崩法",计算_雪崩!BB42,计算_雪球!BB42)) | M23: =IF($A23="","",IF(每月预算!$B$29="雪崩法",计算_雪崩!BC42,计算_雪球!BC42)) -> 3151.34 | N23: =IF($A23="","",IF(每月预算!$B$29="雪崩法",计算_雪崩!BE42,计算_雪球!BE42)) -> 信用卡A | O23: =IF($A23="","",IF(每月预算!$B$29="雪崩法",计算_雪崩!BD42,计算_雪球!BD42)) -> 0
A24: =IF(20<=$R$2,20,"") | B24: =IF($A24="","",计算_雪球!B43) | C24: =IF(OR($A24="",C$4=""),"",IF(每月预算!$B$29="雪崩法",计算_雪崩!I43,计算_雪球!I43)) | D24: =IF(OR($A24="",D$4=""),"",IF(每月预算!$B$29="雪崩法",计算_雪崩!N43,计算_雪球!N43)) | E24: =IF(OR($A24="",E$4=""),"",IF(每月预算!$B$29="雪崩法",计算_雪崩!S43,计算_雪球!S43)) | F24: =IF(OR($A24="",F$4=""),"",IF(每月预算!$B$29="雪崩法",计算_雪崩!X43,计算_雪球!X43)) | G24: =IF(OR($A24="",G$4=""),"",IF(每月预算!$B$29="雪崩法",计算_雪崩!AC43,计算_雪球!AC43)) | H24: =IF(OR($A24="",H$4=""),"",IF(每月预算!$B$29="雪崩法",计算_雪崩!AH43,计算_雪球!AH43)) | I24: =IF(OR($A24="",I$4=""),"",IF(每月预算!$B$29="雪崩法",计算_雪崩!AM43,计算_雪球!AM43)) | J24: =IF(OR($A24="",J$4=""),"",IF(每月预算!$B$29="雪崩法",计算_雪崩!AR43,计算_雪球!AR43)) | K24: =IF(OR($A24="",K$4=""),"",IF(每月预算!$B$29="雪崩法",计算_雪崩!AW43,计算_雪球!AW43)) | L24: =IF(OR($A24="",L$4=""),"",IF(每月预算!$B$29="雪崩法",计算_雪崩!BB43,计算_雪球!BB43)) | M24: =IF($A24="","",IF(每月预算!$B$29="雪崩法",计算_雪崩!BC43,计算_雪球!BC43)) | N24: =IF($A24="","",IF(每月预算!$B$29="雪崩法",计算_雪崩!BE43,计算_雪球!BE43)) | O24: =IF($A24="","",IF(每月预算!$B$29="雪崩法",计算_雪崩!BD43,计算_雪球!BD43))
A25: =IF(21<=$R$2,21,"") | B25: =IF($A25="","",计算_雪球!B44) | C25: =IF(OR($A25="",C$4=""),"",IF(每月预算!$B$29="雪崩法",计算_雪崩!I44,计算_雪球!I44)) | D25: =IF(OR($A25="",D$4=""),"",IF(每月预算!$B$29="雪崩法",计算_雪崩!N44,计算_雪球!N44)) | E25: =IF(OR($A25="",E$4=""),"",IF(每月预算!$B$29="雪崩法",计算_雪崩!S44,计算_雪球!S44)) | F25: =IF(OR($A25="",F$4=""),"",IF(每月预算!$B$29="雪崩法",计算_雪崩!X44,计算_雪球!X44)) | G25: =IF(OR($A25="",G$4=""),"",IF(每月预算!$B$29="雪崩法",计算_雪崩!AC44,计算_雪球!AC44)) | H25: =IF(OR($A25="",H$4=""),"",IF(每月预算!$B$29="雪崩法",计算_雪崩!AH44,计算_雪球!AH44)) | I25: =IF(OR($A25="",I$4=""),"",IF(每月预算!$B$29="雪崩法",计算_雪崩!AM44,计算_雪球!AM44)) | J25: =IF(OR($A25="",J$4=""),"",IF(每月预算!$B$29="雪崩法",计算_雪崩!AR44,计算_雪球!AR44)) | K25: =IF(OR($A25="",K$4=""),"",IF(每月预算!$B$29="雪崩法",计算_雪崩!AW44,计算_雪球!AW44)) | L25: =IF(OR($A25="",L$4=""),"",IF(每月预算!$B$29="雪崩法",计算_雪崩!BB44,计算_雪球!BB44)) | M25: =IF($A25="","",IF(每月预算!$B$29="雪崩法",计算_雪崩!BC44,计算_雪球!BC44)) | N25: =IF($A25="","",IF(每月预算!$B$29="雪崩法",计算_雪崩!BE44,计算_雪球!BE44)) | O25: =IF($A25="","",IF(每月预算!$B$29="雪崩法",计算_雪崩!BD44,计算_雪球!BD44))
A26: =IF(22<=$R$2,22,"") | B26: =IF($A26="","",计算_雪球!B45) | C26: =IF(OR($A26="",C$4=""),"",IF(每月预算!$B$29="雪崩法",计算_雪崩!I45,计算_雪球!I45)) | D26: =IF(OR($A26="",D$4=""),"",IF(每月预算!$B$29="雪崩法",计算_雪崩!N45,计算_雪球!N45)) | E26: =IF(OR($A26="",E$4=""),"",IF(每月预算!$B$29="雪崩法",计算_雪崩!S45,计算_雪球!S45)) | F26: =IF(OR($A26="",F$4=""),"",IF(每月预算!$B$29="雪崩法",计算_雪崩!X45,计算_雪球!X45)) | G26: =IF(OR($A26="",G$4=""),"",IF(每月预算!$B$29="雪崩法",计算_雪崩!AC45,计算_雪球!AC45)) | H26: =IF(OR($A26="",H$4=""),"",IF(每月预算!$B$29="雪崩法",计算_雪崩!AH45,计算_雪球!AH45)) | I26: =IF(OR($A26="",I$4=""),"",IF(每月预算!$B$29="雪崩法",计算_雪崩!AM45,计算_雪球!AM45)) | J26: =IF(OR($A26="",J$4=""),"",IF(每月预算!$B$29="雪崩法",计算_雪崩!AR45,计算_雪球!AR45)) | K26: =IF(OR($A26="",K$4=""),"",IF(每月预算!$B$29="雪崩法",计算_雪崩!AW45,计算_雪球!AW45)) | L26: =IF(OR($A26="",L$4=""),"",IF(每月预算!$B$29="雪崩法",计算_雪崩!BB45,计算_雪球!BB45)) | M26: =IF($A26="","",IF(每月预算!$B$29="雪崩法",计算_雪崩!BC45,计算_雪球!BC45)) | N26: =IF($A26="","",IF(每月预算!$B$29="雪崩法",计算_雪崩!BE45,计算_雪球!BE45)) | O26: =IF($A26="","",IF(每月预算!$B$29="雪崩法",计算_雪崩!BD45,计算_雪球!BD45))
A27: =IF(23<=$R$2,23,"") | B27: =IF($A27="","",计算_雪球!B46) | C27: =IF(OR($A27="",C$4=""),"",IF(每月预算!$B$29="雪崩法",计算_雪崩!I46,计算_雪球!I46)) | D27: =IF(OR($A27="",D$4=""),"",IF(每月预算!$B$29="雪崩法",计算_雪崩!N46,计算_雪球!N46)) | E27: =IF(OR($A27="",E$4=""),"",IF(每月预算!$B$29="雪崩法",计算_雪崩!S46,计算_雪球!S46)) | F27: =IF(OR($A27="",F$4=""),"",IF(每月预算!$B$29="雪崩法",计算_雪崩!X46,计算_雪球!X46)) | G27: =IF(OR($A27="",G$4=""),"",IF(每月预算!$B$29="雪崩法",计算_雪崩!AC46,计算_雪球!AC46)) | H27: =IF(OR($A27="",H$4=""),"",IF(每月预算!$B$29="雪崩法",计算_雪崩!AH46,计算_雪球!AH46)) | I27: =IF(OR($A27="",I$4=""),"",IF(每月预算!$B$29="雪崩法",计算_雪崩!AM46,计算_雪球!AM46)) | J27: =IF(OR($A27="",J$4=""),"",IF(每月预算!$B$29="雪崩法",计算_雪崩!AR46,计算_雪球!AR46)) | K27: =IF(OR($A27="",K$4=""),"",IF(每月预算!$B$29="雪崩法",计算_雪崩!AW46,计算_雪球!AW46)) | L27: =IF(OR($A27="",L$4=""),"",IF(每月预算!$B$29="雪崩法",计算_雪崩!BB46,计算_雪球!BB46)) | M27: =IF($A27="","",IF(每月预算!$B$29="雪崩法",计算_雪崩!BC46,计算_雪球!BC46)) | N27: =IF($A27="","",IF(每月预算!$B$29="雪崩法",计算_雪崩!BE46,计算_雪球!BE46)) | O27: =IF($A27="","",IF(每月预算!$B$29="雪崩法",计算_雪崩!BD46,计算_雪球!BD46))
A28: =IF(24<=$R$2,24,"") | B28: =IF($A28="","",计算_雪球!B47) | C28: =IF(OR($A28="",C$4=""),"",IF(每月预算!$B$29="雪崩法",计算_雪崩!I47,计算_雪球!I47)) | D28: =IF(OR($A28="",D$4=""),"",IF(每月预算!$B$29="雪崩法",计算_雪崩!N47,计算_雪球!N47)) | E28: =IF(OR($A28="",E$4=""),"",IF(每月预算!$B$29="雪崩法",计算_雪崩!S47,计算_雪球!S47)) | F28: =IF(OR($A28="",F$4=""),"",IF(每月预算!$B$29="雪崩法",计算_雪崩!X47,计算_雪球!X47)) | G28: =IF(OR($A28="",G$4=""),"",IF(每月预算!$B$29="雪崩法",计算_雪崩!AC47,计算_雪球!AC47)) | H28: =IF(OR($A28="",H$4=""),"",IF(每月预算!$B$29="雪崩法",计算_雪崩!AH47,计算_雪球!AH47)) | I28: =IF(OR($A28="",I$4=""),"",IF(每月预算!$B$29="雪崩法",计算_雪崩!AM47,计算_雪球!AM47)) | J28: =IF(OR($A28="",J$4=""),"",IF(每月预算!$B$29="雪崩法",计算_雪崩!AR47,计算_雪球!AR47)) | K28: =IF(OR($A28="",K$4=""),"",IF(每月预算!$B$29="雪崩法",计算_雪崩!AW47,计算_雪球!AW47)) | L28: =IF(OR($A28="",L$4=""),"",IF(每月预算!$B$29="雪崩法",计算_雪崩!BB47,计算_雪球!BB47)) | M28: =IF($A28="","",IF(每月预算!$B$29="雪崩法",计算_雪崩!BC47,计算_雪球!BC47)) | N28: =IF($A28="","",IF(每月预算!$B$29="雪崩法",计算_雪崩!BE47,计算_雪球!BE47)) | O28: =IF($A28="","",IF(每月预算!$B$29="雪崩法",计算_雪崩!BD47,计算_雪球!BD47))
A29: =IF(25<=$R$2,25,"") | B29: =IF($A29="","",计算_雪球!B48) | C29: =IF(OR($A29="",C$4=""),"",IF(每月预算!$B$29="雪崩法",计算_雪崩!I48,计算_雪球!I48)) | D29: =IF(OR($A29="",D$4=""),"",IF(每月预算!$B$29="雪崩法",计算_雪崩!N48,计算_雪球!N48)) | E29: =IF(OR($A29="",E$4=""),"",IF(每月预算!$B$29="雪崩法",计算_雪崩!S48,计算_雪球!S48)) | F29: =IF(OR($A29="",F$4=""),"",IF(每月预算!$B$29="雪崩法",计算_雪崩!X48,计算_雪球!X48)) | G29: =IF(OR($A29="",G$4=""),"",IF(每月预算!$B$29="雪崩法",计算_雪崩!AC48,计算_雪球!AC48)) | H29: =IF(OR($A29="",H$4=""),"",IF(每月预算!$B$29="雪崩法",计算_雪崩!AH48,计算_雪球!AH48)) | I29: =IF(OR($A29="",I$4=""),"",IF(每月预算!$B$29="雪崩法",计算_雪崩!AM48,计算_雪球!AM48)) | J29: =IF(OR($A29="",J$4=""),"",IF(每月预算!$B$29="雪崩法",计算_雪崩!AR48,计算_雪球!AR48)) | K29: =IF(OR($A29="",K$4=""),"",IF(每月预算!$B$29="雪崩法",计算_雪崩!AW48,计算_雪球!AW48)) | L29: =IF(OR($A29="",L$4=""),"",IF(每月预算!$B$29="雪崩法",计算_雪崩!BB48,计算_雪球!BB48)) | M29: =IF($A29="","",IF(每月预算!$B$29="雪崩法",计算_雪崩!BC48,计算_雪球!BC48)) | N29: =IF($A29="","",IF(每月预算!$B$29="雪崩法",计算_雪崩!BE48,计算_雪球!BE48)) | O29: =IF($A29="","",IF(每月预算!$B$29="雪崩法",计算_雪崩!BD48,计算_雪球!BD48))
A30: =IF(26<=$R$2,26,"") | B30: =IF($A30="","",计算_雪球!B49) | C30: =IF(OR($A30="",C$4=""),"",IF(每月预算!$B$29="雪崩法",计算_雪崩!I49,计算_雪球!I49)) | D30: =IF(OR($A30="",D$4=""),"",IF(每月预算!$B$29="雪崩法",计算_雪崩!N49,计算_雪球!N49)) | E30: =IF(OR($A30="",E$4=""),"",IF(每月预算!$B$29="雪崩法",计算_雪崩!S49,计算_雪球!S49)) | F30: =IF(OR($A30="",F$4=""),"",IF(每月预算!$B$29="雪崩法",计算_雪崩!X49,计算_雪球!X49)) | G30: =IF(OR($A30="",G$4=""),"",IF(每月预算!$B$29="雪崩法",计算_雪崩!AC49,计算_雪球!AC49)) | H30: =IF(OR($A30="",H$4=""),"",IF(每月预算!$B$29="雪崩法",计算_雪崩!AH49,计算_雪球!AH49)) | I30: =IF(OR($A30="",I$4=""),"",IF(每月预算!$B$29="雪崩法",计算_雪崩!AM49,计算_雪球!AM49)) | J30: =IF(OR($A30="",J$4=""),"",IF(每月预算!$B$29="雪崩法",计算_雪崩!AR49,计算_雪球!AR49)) | K30: =IF(OR($A30="",K$4=""),"",IF(每月预算!$B$29="雪崩法",计算_雪崩!AW49,计算_雪球!AW49)) | L30: =IF(OR($A30="",L$4=""),"",IF(每月预算!$B$29="雪崩法",计算_雪崩!BB49,计算_雪球!BB49)) | M30: =IF($A30="","",IF(每月预算!$B$29="雪崩法",计算_雪崩!BC49,计算_雪球!BC49)) | N30: =IF($A30="","",IF(每月预算!$B$29="雪崩法",计算_雪崩!BE49,计算_雪球!BE49)) | O30: =IF($A30="","",IF(每月预算!$B$29="雪崩法",计算_雪崩!BD49,计算_雪球!BD49))
A31: =IF(27<=$R$2,27,"") | B31: =IF($A31="","",计算_雪球!B50) | C31: =IF(OR($A31="",C$4=""),"",IF(每月预算!$B$29="雪崩法",计算_雪崩!I50,计算_雪球!I50)) | D31: =IF(OR($A31="",D$4=""),"",IF(每月预算!$B$29="雪崩法",计算_雪崩!N50,计算_雪球!N50)) | E31: =IF(OR($A31="",E$4=""),"",IF(每月预算!$B$29="雪崩法",计算_雪崩!S50,计算_雪球!S50)) | F31: =IF(OR($A31="",F$4=""),"",IF(每月预算!$B$29="雪崩法",计算_雪崩!X50,计算_雪球!X50)) | G31: =IF(OR($A31="",G$4=""),"",IF(每月预算!$B$29="雪崩法",计算_雪崩!AC50,计算_雪球!AC50)) | H31: =IF(OR($A31="",H$4=""),"",IF(每月预算!$B$29="雪崩法",计算_雪崩!AH50,计算_雪球!AH50)) | I31: =IF(OR($A31="",I$4=""),"",IF(每月预算!$B$29="雪崩法",计算_雪崩!AM50,计算_雪球!AM50)) | J31: =IF(OR($A31="",J$4=""),"",IF(每月预算!$B$29="雪崩法",计算_雪崩!AR50,计算_雪球!AR50)) | K31: =IF(OR($A31="",K$4=""),"",IF(每月预算!$B$29="雪崩法",计算_雪崩!AW50,计算_雪球!AW50)) | L31: =IF(OR($A31="",L$4=""),"",IF(每月预算!$B$29="雪崩法",计算_雪崩!BB50,计算_雪球!BB50)) | M31: =IF($A31="","",IF(每月预算!$B$29="雪崩法",计算_雪崩!BC50,计算_雪球!BC50)) | N31: =IF($A31="","",IF(每月预算!$B$29="雪崩法",计算_雪崩!BE50,计算_雪球!BE50)) | O31: =IF($A31="","",IF(每月预算!$B$29="雪崩法",计算_雪崩!BD50,计算_雪球!BD50))
A32: =IF(28<=$R$2,28,"") | B32: =IF($A32="","",计算_雪球!B51) | C32: =IF(OR($A32="",C$4=""),"",IF(每月预算!$B$29="雪崩法",计算_雪崩!I51,计算_雪球!I51)) | D32: =IF(OR($A32="",D$4=""),"",IF(每月预算!$B$29="雪崩法",计算_雪崩!N51,计算_雪球!N51)) | E32: =IF(OR($A32="",E$4=""),"",IF(每月预算!$B$29="雪崩法",计算_雪崩!S51,计算_雪球!S51)) | F32: =IF(OR($A32="",F$4=""),"",IF(每月预算!$B$29="雪崩法",计算_雪崩!X51,计算_雪球!X51)) | G32: =IF(OR($A32="",G$4=""),"",IF(每月预算!$B$29="雪崩法",计算_雪崩!AC51,计算_雪球!AC51)) | H32: =IF(OR($A32="",H$4=""),"",IF(每月预算!$B$29="雪崩法",计算_雪崩!AH51,计算_雪球!AH51)) | I32: =IF(OR($A32="",I$4=""),"",IF(每月预算!$B$29="雪崩法",计算_雪崩!AM51,计算_雪球!AM51)) | J32: =IF(OR($A32="",J$4=""),"",IF(每月预算!$B$29="雪崩法",计算_雪崩!AR51,计算_雪球!AR51)) | K32: =IF(OR($A32="",K$4=""),"",IF(每月预算!$B$29="雪崩法",计算_雪崩!AW51,计算_雪球!AW51)) | L32: =IF(OR($A32="",L$4=""),"",IF(每月预算!$B$29="雪崩法",计算_雪崩!BB51,计算_雪球!BB51)) | M32: =IF($A32="","",IF(每月预算!$B$29="雪崩法",计算_雪崩!BC51,计算_雪球!BC51)) | N32: =IF($A32="","",IF(每月预算!$B$29="雪崩法",计算_雪崩!BE51,计算_雪球!BE51)) | O32: =IF($A32="","",IF(每月预算!$B$29="雪崩法",计算_雪崩!BD51,计算_雪球!BD51))
A33: =IF(29<=$R$2,29,"") | B33: =IF($A33="","",计算_雪球!B52) | C33: =IF(OR($A33="",C$4=""),"",IF(每月预算!$B$29="雪崩法",计算_雪崩!I52,计算_雪球!I52)) | D33: =IF(OR($A33="",D$4=""),"",IF(每月预算!$B$29="雪崩法",计算_雪崩!N52,计算_雪球!N52)) | E33: =IF(OR($A33="",E$4=""),"",IF(每月预算!$B$29="雪崩法",计算_雪崩!S52,计算_雪球!S52)) | F33: =IF(OR($A33="",F$4=""),"",IF(每月预算!$B$29="雪崩法",计算_雪崩!X52,计算_雪球!X52)) | G33: =IF(OR($A33="",G$4=""),"",IF(每月预算!$B$29="雪崩法",计算_雪崩!AC52,计算_雪球!AC52)) | H33: =IF(OR($A33="",H$4=""),"",IF(每月预算!$B$29="雪崩法",计算_雪崩!AH52,计算_雪球!AH52)) | I33: =IF(OR($A33="",I$4=""),"",IF(每月预算!$B$29="雪崩法",计算_雪崩!AM52,计算_雪球!AM52)) | J33: =IF(OR($A33="",J$4=""),"",IF(每月预算!$B$29="雪崩法",计算_雪崩!AR52,计算_雪球!AR52)) | K33: =IF(OR($A33="",K$4=""),"",IF(每月预算!$B$29="雪崩法",计算_雪崩!AW52,计算_雪球!AW52)) | L33: =IF(OR($A33="",L$4=""),"",IF(每月预算!$B$29="雪崩法",计算_雪崩!BB52,计算_雪球!BB52)) | M33: =IF($A33="","",IF(每月预算!$B$29="雪崩法",计算_雪崩!BC52,计算_雪球!BC52)) | N33: =IF($A33="","",IF(每月预算!$B$29="雪崩法",计算_雪崩!BE52,计算_雪球!BE52)) | O33: =IF($A33="","",IF(每月预算!$B$29="雪崩法",计算_雪崩!BD52,计算_雪球!BD52))
A34: =IF(30<=$R$2,30,"") | B34: =IF($A34="","",计算_雪球!B53) | C34: =IF(OR($A34="",C$4=""),"",IF(每月预算!$B$29="雪崩法",计算_雪崩!I53,计算_雪球!I53)) | D34: =IF(OR($A34="",D$4=""),"",IF(每月预算!$B$29="雪崩法",计算_雪崩!N53,计算_雪球!N53)) | E34: =IF(OR($A34="",E$4=""),"",IF(每月预算!$B$29="雪崩法",计算_雪崩!S53,计算_雪球!S53)) | F34: =IF(OR($A34="",F$4=""),"",IF(每月预算!$B$29="雪崩法",计算_雪崩!X53,计算_雪球!X53)) | G34: =IF(OR($A34="",G$4=""),"",IF(每月预算!$B$29="雪崩法",计算_雪崩!AC53,计算_雪球!AC53)) | H34: =IF(OR($A34="",H$4=""),"",IF(每月预算!$B$29="雪崩法",计算_雪崩!AH53,计算_雪球!AH53)) | I34: =IF(OR($A34="",I$4=""),"",IF(每月预算!$B$29="雪崩法",计算_雪崩!AM53,计算_雪球!AM53)) | J34: =IF(OR($A34="",J$4=""),"",IF(每月预算!$B$29="雪崩法",计算_雪崩!AR53,计算_雪球!AR53)) | K34: =IF(OR($A34="",K$4=""),"",IF(每月预算!$B$29="雪崩法",计算_雪崩!AW53,计算_雪球!AW53)) | L34: =IF(OR($A34="",L$4=""),"",IF(每月预算!$B$29="雪崩法",计算_雪崩!BB53,计算_雪球!BB53)) | M34: =IF($A34="","",IF(每月预算!$B$29="雪崩法",计算_雪崩!BC53,计算_雪球!BC53)) | N34: =IF($A34="","",IF(每月预算!$B$29="雪崩法",计算_雪崩!BE53,计算_雪球!BE53)) | O34: =IF($A34="","",IF(每月预算!$B$29="雪崩法",计算_雪崩!BD53,计算_雪球!BD53))
A35: =IF(31<=$R$2,31,"") | B35: =IF($A35="","",计算_雪球!B54) | C35: =IF(OR($A35="",C$4=""),"",IF(每月预算!$B$29="雪崩法",计算_雪崩!I54,计算_雪球!I54)) | D35: =IF(OR($A35="",D$4=""),"",IF(每月预算!$B$29="雪崩法",计算_雪崩!N54,计算_雪球!N54)) | E35: =IF(OR($A35="",E$4=""),"",IF(每月预算!$B$29="雪崩法",计算_雪崩!S54,计算_雪球!S54)) | F35: =IF(OR($A35="",F$4=""),"",IF(每月预算!$B$29="雪崩法",计算_雪崩!X54,计算_雪球!X54)) | G35: =IF(OR($A35="",G$4=""),"",IF(每月预算!$B$29="雪崩法",计算_雪崩!AC54,计算_雪球!AC54)) | H35: =IF(OR($A35="",H$4=""),"",IF(每月预算!$B$29="雪崩法",计算_雪崩!AH54,计算_雪球!AH54)) | I35: =IF(OR($A35="",I$4=""),"",IF(每月预算!$B$29="雪崩法",计算_雪崩!AM54,计算_雪球!AM54)) | J35: =IF(OR($A35="",J$4=""),"",IF(每月预算!$B$29="雪崩法",计算_雪崩!AR54,计算_雪球!AR54)) | K35: =IF(OR($A35="",K$4=""),"",IF(每月预算!$B$29="雪崩法",计算_雪崩!AW54,计算_雪球!AW54)) | L35: =IF(OR($A35="",L$4=""),"",IF(每月预算!$B$29="雪崩法",计算_雪崩!BB54,计算_雪球!BB54)) | M35: =IF($A35="","",IF(每月预算!$B$29="雪崩法",计算_雪崩!BC54,计算_雪球!BC54)) | N35: =IF($A35="","",IF(每月预算!$B$29="雪崩法",计算_雪崩!BE54,计算_雪球!BE54)) | O35: =IF($A35="","",IF(每月预算!$B$29="雪崩法",计算_雪崩!BD54,计算_雪球!BD54))
A36: =IF(32<=$R$2,32,"") | B36: =IF($A36="","",计算_雪球!B55) | C36: =IF(OR($A36="",C$4=""),"",IF(每月预算!$B$29="雪崩法",计算_雪崩!I55,计算_雪球!I55)) | D36: =IF(OR($A36="",D$4=""),"",IF(每月预算!$B$29="雪崩法",计算_雪崩!N55,计算_雪球!N55)) | E36: =IF(OR($A36="",E$4=""),"",IF(每月预算!$B$29="雪崩法",计算_雪崩!S55,计算_雪球!S55)) | F36: =IF(OR($A36="",F$4=""),"",IF(每月预算!$B$29="雪崩法",计算_雪崩!X55,计算_雪球!X55)) | G36: =IF(OR($A36="",G$4=""),"",IF(每月预算!$B$29="雪崩法",计算_雪崩!AC55,计算_雪球!AC55)) | H36: =IF(OR($A36="",H$4=""),"",IF(每月预算!$B$29="雪崩法",计算_雪崩!AH55,计算_雪球!AH55)) | I36: =IF(OR($A36="",I$4=""),"",IF(每月预算!$B$29="雪崩法",计算_雪崩!AM55,计算_雪球!AM55)) | J36: =IF(OR($A36="",J$4=""),"",IF(每月预算!$B$29="雪崩法",计算_雪崩!AR55,计算_雪球!AR55)) | K36: =IF(OR($A36="",K$4=""),"",IF(每月预算!$B$29="雪崩法",计算_雪崩!AW55,计算_雪球!AW55)) | L36: =IF(OR($A36="",L$4=""),"",IF(每月预算!$B$29="雪崩法",计算_雪崩!BB55,计算_雪球!BB55)) | M36: =IF($A36="","",IF(每月预算!$B$29="雪崩法",计算_雪崩!BC55,计算_雪球!BC55)) | N36: =IF($A36="","",IF(每月预算!$B$29="雪崩法",计算_雪崩!BE55,计算_雪球!BE55)) | O36: =IF($A36="","",IF(每月预算!$B$29="雪崩法",计算_雪崩!BD55,计算_雪球!BD55))
A37: =IF(33<=$R$2,33,"") | B37: =IF($A37="","",计算_雪球!B56) | C37: =IF(OR($A37="",C$4=""),"",IF(每月预算!$B$29="雪崩法",计算_雪崩!I56,计算_雪球!I56)) | D37: =IF(OR($A37="",D$4=""),"",IF(每月预算!$B$29="雪崩法",计算_雪崩!N56,计算_雪球!N56)) | E37: =IF(OR($A37="",E$4=""),"",IF(每月预算!$B$29="雪崩法",计算_雪崩!S56,计算_雪球!S56)) | F37: =IF(OR($A37="",F$4=""),"",IF(每月预算!$B$29="雪崩法",计算_雪崩!X56,计算_雪球!X56)) | G37: =IF(OR($A37="",G$4=""),"",IF(每月预算!$B$29="雪崩法",计算_雪崩!AC56,计算_雪球!AC56)) | H37: =IF(OR($A37="",H$4=""),"",IF(每月预算!$B$29="雪崩法",计算_雪崩!AH56,计算_雪球!AH56)) | I37: =IF(OR($A37="",I$4=""),"",IF(每月预算!$B$29="雪崩法",计算_雪崩!AM56,计算_雪球!AM56)) | J37: =IF(OR($A37="",J$4=""),"",IF(每月预算!$B$29="雪崩法",计算_雪崩!AR56,计算_雪球!AR56)) | K37: =IF(OR($A37="",K$4=""),"",IF(每月预算!$B$29="雪崩法",计算_雪崩!AW56,计算_雪球!AW56)) | L37: =IF(OR($A37="",L$4=""),"",IF(每月预算!$B$29="雪崩法",计算_雪崩!BB56,计算_雪球!BB56)) | M37: =IF($A37="","",IF(每月预算!$B$29="雪崩法",计算_雪崩!BC56,计算_雪球!BC56)) | N37: =IF($A37="","",IF(每月预算!$B$29="雪崩法",计算_雪崩!BE56,计算_雪球!BE56)) | O37: =IF($A37="","",IF(每月预算!$B$29="雪崩法",计算_雪崩!BD56,计算_雪球!BD56))
A38: =IF(34<=$R$2,34,"") | B38: =IF($A38="","",计算_雪球!B57) | C38: =IF(OR($A38="",C$4=""),"",IF(每月预算!$B$29="雪崩法",计算_雪崩!I57,计算_雪球!I57)) | D38: =IF(OR($A38="",D$4=""),"",IF(每月预算!$B$29="雪崩法",计算_雪崩!N57,计算_雪球!N57)) | E38: =IF(OR($A38="",E$4=""),"",IF(每月预算!$B$29="雪崩法",计算_雪崩!S57,计算_雪球!S57)) | F38: =IF(OR($A38="",F$4=""),"",IF(每月预算!$B$29="雪崩法",计算_雪崩!X57,计算_雪球!X57)) | G38: =IF(OR($A38="",G$4=""),"",IF(每月预算!$B$29="雪崩法",计算_雪崩!AC57,计算_雪球!AC57)) | H38: =IF(OR($A38="",H$4=""),"",IF(每月预算!$B$29="雪崩法",计算_雪崩!AH57,计算_雪球!AH57)) | I38: =IF(OR($A38="",I$4=""),"",IF(每月预算!$B$29="雪崩法",计算_雪崩!AM57,计算_雪球!AM57)) | J38: =IF(OR($A38="",J$4=""),"",IF(每月预算!$B$29="雪崩法",计算_雪崩!AR57,计算_雪球!AR57)) | K38: =IF(OR($A38="",K$4=""),"",IF(每月预算!$B$29="雪崩法",计算_雪崩!AW57,计算_雪球!AW57)) | L38: =IF(OR($A38="",L$4=""),"",IF(每月预算!$B$29="雪崩法",计算_雪崩!BB57,计算_雪球!BB57)) | M38: =IF($A38="","",IF(每月预算!$B$29="雪崩法",计算_雪崩!BC57,计算_雪球!BC57)) | N38: =IF($A38="","",IF(每月预算!$B$29="雪崩法",计算_雪崩!BE57,计算_雪球!BE57)) | O38: =IF($A38="","",IF(每月预算!$B$29="雪崩法",计算_雪崩!BD57,计算_雪球!BD57))
A39: =IF(35<=$R$2,35,"") | B39: =IF($A39="","",计算_雪球!B58) | C39: =IF(OR($A39="",C$4=""),"",IF(每月预算!$B$29="雪崩法",计算_雪崩!I58,计算_雪球!I58)) | D39: =IF(OR($A39="",D$4=""),"",IF(每月预算!$B$29="雪崩法",计算_雪崩!N58,计算_雪球!N58)) | E39: =IF(OR($A39="",E$4=""),"",IF(每月预算!$B$29="雪崩法",计算_雪崩!S58,计算_雪球!S58)) | F39: =IF(OR($A39="",F$4=""),"",IF(每月预算!$B$29="雪崩法",计算_雪崩!X58,计算_雪球!X58)) | G39: =IF(OR($A39="",G$4=""),"",IF(每月预算!$B$29="雪崩法",计算_雪崩!AC58,计算_雪球!AC58)) | H39: =IF(OR($A39="",H$4=""),"",IF(每月预算!$B$29="雪崩法",计算_雪崩!AH58,计算_雪球!AH58)) | I39: =IF(OR($A39="",I$4=""),"",IF(每月预算!$B$29="雪崩法",计算_雪崩!AM58,计算_雪球!AM58)) | J39: =IF(OR($A39="",J$4=""),"",IF(每月预算!$B$29="雪崩法",计算_雪崩!AR58,计算_雪球!AR58)) | K39: =IF(OR($A39="",K$4=""),"",IF(每月预算!$B$29="雪崩法",计算_雪崩!AW58,计算_雪球!AW58)) | L39: =IF(OR($A39="",L$4=""),"",IF(每月预算!$B$29="雪崩法",计算_雪崩!BB58,计算_雪球!BB58)) | M39: =IF($A39="","",IF(每月预算!$B$29="雪崩法",计算_雪崩!BC58,计算_雪球!BC58)) | N39: =IF($A39="","",IF(每月预算!$B$29="雪崩法",计算_雪崩!BE58,计算_雪球!BE58)) | O39: =IF($A39="","",IF(每月预算!$B$29="雪崩法",计算_雪崩!BD58,计算_雪球!BD58))
A40: =IF(36<=$R$2,36,"") | B40: =IF($A40="","",计算_雪球!B59) | C40: =IF(OR($A40="",C$4=""),"",IF(每月预算!$B$29="雪崩法",计算_雪崩!I59,计算_雪球!I59)) | D40: =IF(OR($A40="",D$4=""),"",IF(每月预算!$B$29="雪崩法",计算_雪崩!N59,计算_雪球!N59)) | E40: =IF(OR($A40="",E$4=""),"",IF(每月预算!$B$29="雪崩法",计算_雪崩!S59,计算_雪球!S59)) | F40: =IF(OR($A40="",F$4=""),"",IF(每月预算!$B$29="雪崩法",计算_雪崩!X59,计算_雪球!X59)) | G40: =IF(OR($A40="",G$4=""),"",IF(每月预算!$B$29="雪崩法",计算_雪崩!AC59,计算_雪球!AC59)) | H40: =IF(OR($A40="",H$4=""),"",IF(每月预算!$B$29="雪崩法",计算_雪崩!AH59,计算_雪球!AH59)) | I40: =IF(OR($A40="",I$4=""),"",IF(每月预算!$B$29="雪崩法",计算_雪崩!AM59,计算_雪球!AM59)) | J40: =IF(OR($A40="",J$4=""),"",IF(每月预算!$B$29="雪崩法",计算_雪崩!AR59,计算_雪球!AR59)) | K40: =IF(OR($A40="",K$4=""),"",IF(每月预算!$B$29="雪崩法",计算_雪崩!AW59,计算_雪球!AW59)) | L40: =IF(OR($A40="",L$4=""),"",IF(每月预算!$B$29="雪崩法",计算_雪崩!BB59,计算_雪球!BB59)) | M40: =IF($A40="","",IF(每月预算!$B$29="雪崩法",计算_雪崩!BC59,计算_雪球!BC59)) | N40: =IF($A40="","",IF(每月预算!$B$29="雪崩法",计算_雪崩!BE59,计算_雪球!BE59)) | O40: =IF($A40="","",IF(每月预算!$B$29="雪崩法",计算_雪崩!BD59,计算_雪球!BD59))
A41: =IF(37<=$R$2,37,"") | B41: =IF($A41="","",计算_雪球!B60) | C41: =IF(OR($A41="",C$4=""),"",IF(每月预算!$B$29="雪崩法",计算_雪崩!I60,计算_雪球!I60)) | D41: =IF(OR($A41="",D$4=""),"",IF(每月预算!$B$29="雪崩法",计算_雪崩!N60,计算_雪球!N60)) | E41: =IF(OR($A41="",E$4=""),"",IF(每月预算!$B$29="雪崩法",计算_雪崩!S60,计算_雪球!S60)) | F41: =IF(OR($A41="",F$4=""),"",IF(每月预算!$B$29="雪崩法",计算_雪崩!X60,计算_雪球!X60)) | G41: =IF(OR($A41="",G$4=""),"",IF(每月预算!$B$29="雪崩法",计算_雪崩!AC60,计算_雪球!AC60)) | H41: =IF(OR($A41="",H$4=""),"",IF(每月预算!$B$29="雪崩法",计算_雪崩!AH60,计算_雪球!AH60)) | I41: =IF(OR($A41="",I$4=""),"",IF(每月预算!$B$29="雪崩法",计算_雪崩!AM60,计算_雪球!AM60)) | J41: =IF(OR($A41="",J$4=""),"",IF(每月预算!$B$29="雪崩法",计算_雪崩!AR60,计算_雪球!AR60)) | K41: =IF(OR($A41="",K$4=""),"",IF(每月预算!$B$29="雪崩法",计算_雪崩!AW60,计算_雪球!AW60)) | L41: =IF(OR($A41="",L$4=""),"",IF(每月预算!$B$29="雪崩法",计算_雪崩!BB60,计算_雪球!BB60)) | M41: =IF($A41="","",IF(每月预算!$B$29="雪崩法",计算_雪崩!BC60,计算_雪球!BC60)) | N41: =IF($A41="","",IF(每月预算!$B$29="雪崩法",计算_雪崩!BE60,计算_雪球!BE60)) | O41: =IF($A41="","",IF(每月预算!$B$29="雪崩法",计算_雪崩!BD60,计算_雪球!BD60))
...

Sheet 利率换算
A1: 利率换算：把各种说法换成真实年化
A2: 填黄底蓝字的格子，绿底的就是真实年化。算出来的年化填回「债务清单」。
A4: ① 日息（比如“日息万五”）
A5: 日利率 | B5: 0.0005 | C5: 万五 = 0.05%
A6: 年化（单利） | B6: =B5*365 -> 0.1825
A8: ② 月息（比如“月息 1.5%”）
A9: 月利率 | B9: 0.015
A10: 年化 | B10: =B9*12 -> 0.18
A12: ③ 分期手续费（每期按最初总额收手续费）
A13: 分期金额（元） | B13: 12000
A14: 分几期 | B14: 12
A15: 每期手续费率 | B15: 0.006
A16: 每期要还 | B16: =B13/B14+B13*B15 -> 1072
A17: 手续费一共多少 | B17: =B13*B15*B14 -> 864
A18: 表面上的年费率 | B18: =B15*12 -> 0.072 | C18: 很多人以为是这个数
A19: 真实年化 | B19: =RATE(B14,-B16,B13)*12 -> 0.13034224 | C19: 你欠的钱每个月在变少，手续费却按最初总额收，所以真实年化接近表面的两倍
A21: ④ 只知道借到手多少、每期还多少（网贷常见）
A22: 实际到手多少（元） | B22: 10000 | C22: 被提前扣掉的“服务费”“砍头息”不算到手
A23: 分几期（按月） | B23: 12
A24: 每期还多少（元） | B24: 1000
A25: 一共多还了多少 | B25: =B23*B24-B22 -> 2000
A26: 真实年化 | B26: =RATE(B23,-B24,B22)*12 -> 0.35074249 | C26: =IF(B26>0.24,"超过 24%：持牌机构的个人贷款可以打 12378 投诉","") -> 超过 24%：持牌机构的个人贷款可以打 12378 投诉

Sheet 计算_雪球
A1: 自动计算（雪球法）—— 这一页不用改
A2: 每月利息 = 欠款 × 年化 ÷ 12；先还所有最低还款，剩下的钱按顺序砸向排在最前面的债。
A4: 顺序 | B4: 清单第几行 | C4: 名称 | D4: 初始欠款 | E4: 年化 | F4: 每月最低还款 | G4: 第几个月还清 | H4: 总利息
A5: 1 | B5: =IFERROR(MATCH(A5,债务清单!$J$5:$J$14,0),"") -> 2 | C5: =IF(B5="","",INDEX(债务清单!$B$5:$B$14,B5)) -> 信用卡B（分期） | D5: =IF(B5="",0,INDEX(债务清单!$D$5:$D$14,B5)) -> 12000 | E5: =IF(B5="",0,INDEX(债务清单!$O$5:$O$14,B5)) -> 0.13 | F5: =IF(B5="",0,N(INDEX(债务清单!$F$5:$F$14,B5))) -> 1072 | G5: =IF(D5<=0,"",IF(E263+F263-I263>0.01,"超过20年",COUNTIF(E24:E263,">0.005"))) -> 7 | H5: =SUM(F24:F263) -> 460.13
A6: 2 | B6: =IFERROR(MATCH(A6,债务清单!$J$5:$J$14,0),"") -> 4 | C6: =IF(B6="","",INDEX(债务清单!$B$5:$B$14,B6)) -> 亲友借款（老王） | D6: =IF(B6="",0,INDEX(债务清单!$D$5:$D$14,B6)) -> 20000 | E6: =IF(B6="",0,INDEX(债务清单!$O$5:$O$14,B6)) -> 0 | F6: =IF(B6="",0,N(INDEX(债务清单!$F$5:$F$14,B6))) -> 500 | G6: =IF(D6<=0,"",IF(J263+K263-N263>0.01,"超过20年",COUNTIF(J24:J263,">0.005"))) -> 13 | H6: =SUM(K24:K263) -> 0
A7: 3 | B7: =IFERROR(MATCH(A7,债务清单!$J$5:$J$14,0),"") -> 3 | C7: =IF(B7="","",INDEX(债务清单!$B$5:$B$14,B7)) -> 网贷X | D7: =IF(B7="",0,INDEX(债务清单!$D$5:$D$14,B7)) -> 25000 | E7: =IF(B7="",0,INDEX(债务清单!$O$5:$O$14,B7)) -> 0.24 | F7: =IF(B7="",0,N(INDEX(债务清单!$F$5:$F$14,B7))) -> 1350 | G7: =IF(D7<=0,"",IF(O263+P263-S263>0.01,"超过20年",COUNTIF(O24:O263,">0.005"))) -> 17 | H7: =SUM(P24:P263) -> 5546.51
A8: 4 | B8: =IFERROR(MATCH(A8,债务清单!$J$5:$J$14,0),"") -> 1 | C8: =IF(B8="","",INDEX(债务清单!$B$5:$B$14,B8)) -> 信用卡A | D8: =IF(B8="",0,INDEX(债务清单!$D$5:$D$14,B8)) -> 38000 | E8: =IF(B8="",0,INDEX(债务清单!$O$5:$O$14,B8)) -> 0.18 | F8: =IF(B8="",0,N(INDEX(债务清单!$F$5:$F$14,B8))) -> 1900 | G8: =IF(D8<=0,"",IF(T263+U263-X263>0.01,"超过20年",COUNTIF(T24:T263,">0.005"))) -> 19 | H8: =SUM(U24:U263) -> 6940.7
A9: 5 | B9: =IFERROR(MATCH(A9,债务清单!$J$5:$J$14,0),"") | C9: =IF(B9="","",INDEX(债务清单!$B$5:$B$14,B9)) | D9: =IF(B9="",0,INDEX(债务清单!$D$5:$D$14,B9)) -> 0 | E9: =IF(B9="",0,INDEX(债务清单!$O$5:$O$14,B9)) -> 0 | F9: =IF(B9="",0,N(INDEX(债务清单!$F$5:$F$14,B9))) -> 0 | G9: =IF(D9<=0,"",IF(Y263+Z263-AC263>0.01,"超过20年",COUNTIF(Y24:Y263,">0.005"))) | H9: =SUM(Z24:Z263) -> 0
A10: 6 | B10: =IFERROR(MATCH(A10,债务清单!$J$5:$J$14,0),"") | C10: =IF(B10="","",INDEX(债务清单!$B$5:$B$14,B10)) | D10: =IF(B10="",0,INDEX(债务清单!$D$5:$D$14,B10)) -> 0 | E10: =IF(B10="",0,INDEX(债务清单!$O$5:$O$14,B10)) -> 0 | F10: =IF(B10="",0,N(INDEX(债务清单!$F$5:$F$14,B10))) -> 0 | G10: =IF(D10<=0,"",IF(AD263+AE263-AH263>0.01,"超过20年",COUNTIF(AD24:AD263,">0.005"))) | H10: =SUM(AE24:AE263) -> 0
A11: 7 | B11: =IFERROR(MATCH(A11,债务清单!$J$5:$J$14,0),"") | C11: =IF(B11="","",INDEX(债务清单!$B$5:$B$14,B11)) | D11: =IF(B11="",0,INDEX(债务清单!$D$5:$D$14,B11)) -> 0 | E11: =IF(B11="",0,INDEX(债务清单!$O$5:$O$14,B11)) -> 0 | F11: =IF(B11="",0,N(INDEX(债务清单!$F$5:$F$14,B11))) -> 0 | G11: =IF(D11<=0,"",IF(AI263+AJ263-AM263>0.01,"超过20年",COUNTIF(AI24:AI263,">0.005"))) | H11: =SUM(AJ24:AJ263) -> 0
A12: 8 | B12: =IFERROR(MATCH(A12,债务清单!$J$5:$J$14,0),"") | C12: =IF(B12="","",INDEX(债务清单!$B$5:$B$14,B12)) | D12: =IF(B12="",0,INDEX(债务清单!$D$5:$D$14,B12)) -> 0 | E12: =IF(B12="",0,INDEX(债务清单!$O$5:$O$14,B12)) -> 0 | F12: =IF(B12="",0,N(INDEX(债务清单!$F$5:$F$14,B12))) -> 0 | G12: =IF(D12<=0,"",IF(AN263+AO263-AR263>0.01,"超过20年",COUNTIF(AN24:AN263,">0.005"))) | H12: =SUM(AO24:AO263) -> 0
A13: 9 | B13: =IFERROR(MATCH(A13,债务清单!$J$5:$J$14,0),"") | C13: =IF(B13="","",INDEX(债务清单!$B$5:$B$14,B13)) | D13: =IF(B13="",0,INDEX(债务清单!$D$5:$D$14,B13)) -> 0 | E13: =IF(B13="",0,INDEX(债务清单!$O$5:$O$14,B13)) -> 0 | F13: =IF(B13="",0,N(INDEX(债务清单!$F$5:$F$14,B13))) -> 0 | G13: =IF(D13<=0,"",IF(AS263+AT263-AW263>0.01,"超过20年",COUNTIF(AS24:AS263,">0.005"))) | H13: =SUM(AT24:AT263) -> 0
A14: 10 | B14: =IFERROR(MATCH(A14,债务清单!$J$5:$J$14,0),"") | C14: =IF(B14="","",INDEX(债务清单!$B$5:$B$14,B14)) | D14: =IF(B14="",0,INDEX(债务清单!$D$5:$D$14,B14)) -> 0 | E14: =IF(B14="",0,INDEX(债务清单!$O$5:$O$14,B14)) -> 0 | F14: =IF(B14="",0,N(INDEX(债务清单!$F$5:$F$14,B14))) -> 0 | G14: =IF(D14<=0,"",IF(AX263+AY263-BB263>0.01,"超过20年",COUNTIF(AX24:AX263,">0.005"))) | H14: =SUM(AY24:AY263) -> 0
A16: 每月还款总预算 | C16: =每月预算!B27 -> 5822
A17: 开始月份 | C17: =每月预算!B30 -> 46327
A18: 还清需要几个月 | C18: =IF(COUNTIF(G5:G14,"超过20年")>0,"超过20年",IF(COUNT(G5:G14)=0,0,MAX(G5:G14))) -> 19
A19: 总利息 | C19: =SUM(H5:H14) -> 12947.34
A20: 第一笔还清是第几个月 | C20: =IF(COUNT(G5:G14)=0,"",MIN(G5:G14)) -> 7
E22: =IF(C5="","第1笔（空）","第1笔："&C5) -> 第1笔：信用卡B（分期） | J22: =IF(C6="","第2笔（空）","第2笔："&C6) -> 第2笔：亲友借款（老王） | O22: =IF(C7="","第3笔（空）","第3笔："&C7) -> 第3笔：网贷X | T22: =IF(C8="","第4笔（空）","第4笔："&C8) -> 第4笔：信用卡A | Y22: =IF(C9="","第5笔（空）","第5笔："&C9) -> 第5笔（空） | AD22: =IF(C10="","第6笔（空）","第6笔："&C10) -> 第6笔（空） | AI22: =IF(C11="","第7笔（空）","第7笔："&C11) -> 第7笔（空） | AN22: =IF(C12="","第8笔（空）","第8笔："&C12) -> 第8笔（空） | AS22: =IF(C13="","第9笔（空）","第9笔："&C13) -> 第9笔（空） | AX22: =IF(C14="","第10笔（空）","第10笔："&C14) -> 第10笔（空）
A23: 月份 | B23: 日期 | C23: 最低还款部分合计 | D23: 可加速的钱 | E23: 月初欠款 | F23: 利息 | G23: 最低还款部分 | H23: 加速部分 | I23: 本月还款 | J23: 月初欠款 | K23: 利息 | L23: 最低还款部分 | M23: 加速部分 | N23: 本月还款 | O23: 月初欠款 | P23: 利息 | Q23: 最低还款部分 | R23: 加速部分 | S23: 本月还款 | T23: 月初欠款 | U23: 利息 | V23: 最低还款部分 | W23: 加速部分 | X23: 本月还款 | Y23: 月初欠款 | Z23: 利息 | AA23: 最低还款部分 | AB23: 加速部分 | AC23: 本月还款 | AD23: 月初欠款 | AE23: 利息 | AF23: 最低还款部分 | AG23: 加速部分 | AH23: 本月还款 | AI23: 月初欠款 | AJ23: 利息 | AK23: 最低还款部分 | AL23: 加速部分 | AM23: 本月还款 | AN23: 月初欠款 | AO23: 利息 | AP23: 最低还款部分 | AQ23: 加速部分 | AR23: 本月还款 | AS23: 月初欠款 | AT23: 利息 | AU23: 最低还款部分 | AV23: 加速部分 | AW23: 本月还款 | AX23: 月初欠款 | AY23: 利息 | AZ23: 最低还款部分 | BA23: 加速部分 | BB23: 本月还款 | BC23: 本月还款合计 | BD23: 月末还剩合计 | BE23: 加速钱给了
A24: 1 | B24: =EDATE($C$17,A24-1) -> 46327 | C24: =G24+L24+Q24+V24+AA24+AF24+AK24+AP24+AU24+AZ24 -> 4822 | D24: =MAX(0,$C$16-C24) -> 1000 | E24: =$D$5 -> 12000 | F24: =ROUND(E24*$E$5/12,2) -> 130 | G24: =MIN($F$5,E24+F24) -> 1072 | H24: =MAX(0,MIN(E24+F24-G24,$D24)) -> 1000 | I24: =G24+H24 -> 2072 | J24: =$D$6 -> 20000 | K24: =ROUND(J24*$E$6/12,2) -> 0 | L24: =MIN($F$6,J24+K24) -> 500 | M24: =MAX(0,MIN(J24+K24-L24,$D24-(H24))) -> 0 | N24: =L24+M24 -> 500 | O24: =$D$7 -> 25000 | P24: =ROUND(O24*$E$7/12,2) -> 500 | Q24: =MIN($F$7,O24+P24) -> 1350 | R24: =MAX(0,MIN(O24+P24-Q24,$D24-(H24+M24))) -> 0 | S24: =Q24+R24 -> 1350 | T24: =$D$8 -> 38000 | U24: =ROUND(T24*$E$8/12,2) -> 570 | V24: =MIN($F$8,T24+U24) -> 1900 | W24: =MAX(0,MIN(T24+U24-V24,$D24-(H24+M24+R24))) -> 0 | X24: =V24+W24 -> 1900 | Y24: =$D$9 -> 0 | Z24: =ROUND(Y24*$E$9/12,2) -> 0 | AA24: =MIN($F$9,Y24+Z24) -> 0 | AB24: =MAX(0,MIN(Y24+Z24-AA24,$D24-(H24+M24+R24+W24))) -> 0 | AC24: =AA24+AB24 -> 0 | AD24: =$D$10 -> 0 | AE24: =ROUND(AD24*$E$10/12,2) -> 0 | AF24: =MIN($F$10,AD24+AE24) -> 0 | AG24: =MAX(0,MIN(AD24+AE24-AF24,$D24-(H24+M24+R24+W24+AB24))) -> 0 | AH24: =AF24+AG24 -> 0 | AI24: =$D$11 -> 0 | AJ24: =ROUND(AI24*$E$11/12,2) -> 0 | AK24: =MIN($F$11,AI24+AJ24) -> 0 | AL24: =MAX(0,MIN(AI24+AJ24-AK24,$D24-(H24+M24+R24+W24+AB24+AG24))) -> 0 | AM24: =AK24+AL24 -> 0 | AN24: =$D$12 -> 0 | AO24: =ROUND(AN24*$E$12/12,2) -> 0 | AP24: =MIN($F$12,AN24+AO24) -> 0 | AQ24: =MAX(0,MIN(AN24+AO24-AP24,$D24-(H24+M24+R24+W24+AB24+AG24+AL24))) -> 0 | AR24: =AP24+AQ24 -> 0 | AS24: =$D$13 -> 0 | AT24: =ROUND(AS24*$E$13/12,2) -> 0 | AU24: =MIN($F$13,AS24+AT24) -> 0 | AV24: =MAX(0,MIN(AS24+AT24-AU24,$D24-(H24+M24+R24+W24+AB24+AG24+AL24+AQ24))) -> 0 | AW24: =AU24+AV24 -> 0 | AX24: =$D$14 -> 0 | AY24: =ROUND(AX24*$E$14/12,2) -> 0 | AZ24: =MIN($F$14,AX24+AY24) -> 0 | BA24: =MAX(0,MIN(AX24+AY24-AZ24,$D24-(H24+M24+R24+W24+AB24+AG24+AL24+AQ24+AV24))) -> 0 | BB24: =AZ24+BA24 -> 0 | BC24: =I24+N24+S24+X24+AC24+AH24+AM24+AR24+AW24+BB24 -> 5822 | BD24: =ROUND((E24+F24-I24)+(J24+K24-N24)+(O24+P24-S24)+(T24+U24-X24)+(Y24+Z24-AC24)+(AD24+AE24-AH24)+(AI24+AJ24-AM24)+(AN24+AO24-AR24)+(AS24+AT24-AW24)+(AX24+AY24-BB24),2) -> 90378 | BE24: =IF(H24>0.005,$C$5,IF(M24>0.005,$C$6,IF(R24>0.005,$C$7,IF(W24>0.005,$C$8,IF(AB24>0.005,$C$9,IF(AG24>0.005,$C$10,IF(AL24>0.005,$C$11,IF(AQ24>0.005,$C$12,IF(AV24>0.005,$C$13,IF(BA24>0.005,$C$14,"")))))))))) -> 信用卡B（分期）
A25: 2 | B25: =EDATE($C$17,A25-1) -> 46357 | C25: =G25+L25+Q25+V25+AA25+AF25+AK25+AP25+AU25+AZ25 -> 4822 | D25: =MAX(0,$C$16-C25) -> 1000 | E25: =ROUND(MAX(0,E24+F24-I24),2) -> 10058 | F25: =ROUND(E25*$E$5/12,2) -> 108.96 | G25: =MIN($F$5,E25+F25) -> 1072 | H25: =MAX(0,MIN(E25+F25-G25,$D25)) -> 1000 | I25: =G25+H25 -> 2072 | J25: =ROUND(MAX(0,J24+K24-N24),2) -> 19500 | K25: =ROUND(J25*$E$6/12,2) -> 0 | L25: =MIN($F$6,J25+K25) -> 500 | M25: =MAX(0,MIN(J25+K25-L25,$D25-(H25))) -> 0 | N25: =L25+M25 -> 500 | O25: =ROUND(MAX(0,O24+P24-S24),2) -> 24150 | P25: =ROUND(O25*$E$7/12,2) -> 483 | Q25: =MIN($F$7,O25+P25) -> 1350 | R25: =MAX(0,MIN(O25+P25-Q25,$D25-(H25+M25))) -> 0 | S25: =Q25+R25 -> 1350 | T25: =ROUND(MAX(0,T24+U24-X24),2) -> 36670 | U25: =ROUND(T25*$E$8/12,2) -> 550.05 | V25: =MIN($F$8,T25+U25) -> 1900 | W25: =MAX(0,MIN(T25+U25-V25,$D25-(H25+M25+R25))) -> 0 | X25: =V25+W25 -> 1900 | Y25: =ROUND(MAX(0,Y24+Z24-AC24),2) -> 0 | Z25: =ROUND(Y25*$E$9/12,2) -> 0 | AA25: =MIN($F$9,Y25+Z25) -> 0 | AB25: =MAX(0,MIN(Y25+Z25-AA25,$D25-(H25+M25+R25+W25))) -> 0 | AC25: =AA25+AB25 -> 0 | AD25: =ROUND(MAX(0,AD24+AE24-AH24),2) -> 0 | AE25: =ROUND(AD25*$E$10/12,2) -> 0 | AF25: =MIN($F$10,AD25+AE25) -> 0 | AG25: =MAX(0,MIN(AD25+AE25-AF25,$D25-(H25+M25+R25+W25+AB25))) -> 0 | AH25: =AF25+AG25 -> 0 | AI25: =ROUND(MAX(0,AI24+AJ24-AM24),2) -> 0 | AJ25: =ROUND(AI25*$E$11/12,2) -> 0 | AK25: =MIN($F$11,AI25+AJ25) -> 0 | AL25: =MAX(0,MIN(AI25+AJ25-AK25,$D25-(H25+M25+R25+W25+AB25+AG25))) -> 0 | AM25: =AK25+AL25 -> 0 | AN25: =ROUND(MAX(0,AN24+AO24-AR24),2) -> 0 | AO25: =ROUND(AN25*$E$12/12,2) -> 0 | AP25: =MIN($F$12,AN25+AO25) -> 0 | AQ25: =MAX(0,MIN(AN25+AO25-AP25,$D25-(H25+M25+R25+W25+AB25+AG25+AL25))) -> 0 | AR25: =AP25+AQ25 -> 0 | AS25: =ROUND(MAX(0,AS24+AT24-AW24),2) -> 0 | AT25: =ROUND(AS25*$E$13/12,2) -> 0 | AU25: =MIN($F$13,AS25+AT25) -> 0 | AV25: =MAX(0,MIN(AS25+AT25-AU25,$D25-(H25+M25+R25+W25+AB25+AG25+AL25+AQ25))) -> 0 | AW25: =AU25+AV25 -> 0 | AX25: =ROUND(MAX(0,AX24+AY24-BB24),2) -> 0 | AY25: =ROUND(AX25*$E$14/12,2) -> 0 | AZ25: =MIN($F$14,AX25+AY25) -> 0 | BA25: =MAX(0,MIN(AX25+AY25-AZ25,$D25-(H25+M25+R25+W25+AB25+AG25+AL25+AQ25+AV25))) -> 0 | BB25: =AZ25+BA25 -> 0 | BC25: =I25+N25+S25+X25+AC25+AH25+AM25+AR25+AW25+BB25 -> 5822 | BD25: =ROUND((E25+F25-I25)+(J25+K25-N25)+(O25+P25-S25)+(T25+U25-X25)+(Y25+Z25-AC25)+(AD25+AE25-AH25)+(AI25+AJ25-AM25)+(AN25+AO25-AR25)+(AS25+AT25-AW25)+(AX25+AY25-BB25),2) -> 85698.01 | BE25: =IF(H25>0.005,$C$5,IF(M25>0.005,$C$6,IF(R25>0.005,$C$7,IF(W25>0.005,$C$8,IF(AB25>0.005,$C$9,IF(AG25>0.005,$C$10,IF(AL25>0.005,$C$11,IF(AQ25>0.005,$C$12,IF(AV25>0.005,$C$13,IF(BA25>0.005,$C$14,"")))))))))) -> 信用卡B（分期）
